Workbook

Sheet MAPA_OBRA_707
A1: Artº | B1: Designação de Trabalhos | C1: Un. | D1: Quant.
A2: 4.1 | B2: Betão de Limpeza / Cleaning concrete
A3: 4.1.1 | B3: Fornecimento e aplicação de betão de limpeza do tipo C16/20 X0 numa espessura de 0,10 m. | C3: m3 | D3: 172.56
A4: 4.2 | B4: Fundações / Foundations
A5: 4.2.1 | B5: Fornecimento e colocação de betão armado C30/37 XC2 0,40 Dmáx 22 S3 , em sapatas de muros e paredes, incluindo o fornecimento, aplicação e desmontagem de cofragem e o fornecimento, moldagem e aplicação de aço A500NR. Todos os trabalhos deverão ser executados de acordo com as peças desenhadas:
A6: 4.2.1.1 | B6: Sapatas Isoladas / Isolated Foundations (90 kg/m3)
B7: Betão - Aplicação e Vibração | C7: m3 | D7: 163.87
B8: Cofragem - Fornecimento e aplicação | C8: m2 | D8: 409.68
B9: Aço - Moldagem, Corte e Aplicação | C9: kg | D9: 16960.55
A10: 4.2.1.2 | B10: Sapatas Contínuas / Continuous Foundations (110 kg/m3)
B11: Betão - Aplicação e Vibração | C11: m3 | D11: 155.53
B12: Cofragem - Fornecimento e aplicação | C12: m2 | D12: 388.83
B13: Aço - Moldagem, Corte e Aplicação | C13: kg | D13: 19674.67
A14: 4.2.1.3 | B14: Vigas de Fundação / Beams of Foundations (115 kg/m3)
B15: Betão - Aplicação e Vibração | C15: m3 | D15: 61.44
B16: Cofragem - Fornecimento e aplicação | C16: m2 | D16: 688.74
B17: Aço - Moldagem, Corte e Aplicação | C17: kg | D17: 8125.44
A18: 4.3 | B18: Superestrutura / Superstructure
A19: 4.3.1 | B19: Fornecimento e colocação de betão armado C30/37 XC1 Cl 0,20 Dmáx 20 S3 , em Muros, pilares, paredes, vigas e lajes, incluindo o fornecimento, aplicação e desmontagem de cofragem e o fornecimento, moldagem e aplicação de aço A500NR com a referida taxa de armaduras. Todos os trabalhos deverão ser executados de acordo com as peças desenhadas:
A20: 4.3.1.1 | B20: Muros Enterrados / Buried Walls (115 kg/m3)
B21: Betão - Aplicação e Vibração | C21: m3 | D21: 357.21
B22: Cofragem - Fornecimento e aplicação | C22: m2 | D22: 3597.09
B23: Aço - Moldagem, Corte e Aplicação | C23: kg | D23: 53583.49
A24: 4.3.1.2 | B24: Pilares / Columns (290 kg/m3)
B25: Betão - Aplicação e Vibração | C25: m3 | D25: 175.75
B26: Cofragem - Fornecimento e aplicação | C26: m2 | D26: 1933.25
B27: Aço - Moldagem, Corte e Aplicação | C27: kg | D27: 58612.63
A28: 4.3.1.3 | B28: Paredes / Walls (200 kg/m3)
B29: Betão - Aplicação e Vibração | C29: m3 | D29: 55.41
B30: Cofragem - Fornecimento e aplicação | C30: m2 | D30: 554.1
B31: Aço - Moldagem, Corte e Aplicação | C31: kg | D31: 12744.3
A32: 4.3.1.3 A | B32: Núcleos do Elevador / Elevator Shaft (200 kg/m3)
B33: Betão - Aplicação e Vibração | C33: m3 | D33: 168.52
B34: Cofragem - Fornecimento e aplicação | C34: m2 | D34: 1862.19
B35: Aço - Moldagem, Corte e Aplicação | C35: kg | D35: 38760.52
A36: 4.3.1.4 | B36: Vigas / Beams (150 kg/m3)
B37: Betão - Aplicação e Vibração | C37: m3 | D37: 384.7
B38: Cofragem - Fornecimento e aplicação | C38: m2 | D38: 3847
B39: Aço - Moldagem, Corte e Aplicação | C39: kg | D39: 66360.75
A40: 4.3.1.5 | B40: Lajes Maciças / Massive Slabs (120 kg/m3)
...

Sheet PISOS
A1: CADASTRO DE PAVIMENTOS
A2: Nome do Piso | B2: Cota Inferior (m) | C2: Cota Superior (m) | D2: Altura do Trecho (m)
A3: Fund+Piso -1 | B3: -5.1 | C3: -1.2 | D3: =IF(COUNT(B3,C3)=2,C3-B3,"PENDENTE") -> 3.9
A4: Fundações | B4: -5.1 | C4: -4.7 | D4: =IF(COUNT(B4,C4)=2,C4-B4,"PENDENTE") -> 0.4 | E4: =IF(COUNT(C4,D4)=2,D4-C4,"PENDENTE") -> 5.1
A5: Piso -1 | B5: -4.7 | C5: -1.2 | D5: =IF(COUNT(B5,C5)=2,C5-B5,"PENDENTE") -> 3.5 | E5: =IF(COUNT(C5,D5)=2,D5-C5,"PENDENTE") -> 4.7
A6: Piso 1 | B6: -1.43 | C6: 2.5 | D6: =IF(COUNT(B6,C6)=2,C6-B6,"PENDENTE") -> 3.93 | E6: =IF(COUNT(C6,D6)=2,D6-C6,"PENDENTE") -> 1.43
A7: Cobertura | D7: =IF(COUNT(B7,C7)=2,C7-B7,"PENDENTE") -> PENDENTE | E7: =IF(COUNT(C7,D7)=2,D7-C7,"PENDENTE") -> PENDENTE
A9: O desenho 05 não fornece cotas de pisos. Introduzir cotas confirmadas nos cortes do projeto. H=3,90 m foi mantida apenas no P8-P1.

Sheet PILARES (G)
A1: LEVANTAMENTO DE AÇO — PILARES
A2: Azul=entrada | Bege=transpasse | Verde=calculado | Laranja=ferro total | Roxo=betão | Amarelo=cofragem
A4: GEOMETRIA / SEÇÃO | G4: TRANSPASSE / ARRANQUE | J4: ARM. LONGITUDINAL | P4: EST. TIPO 1 | S4: EST. TIPO 2 | V4: EST. TIPO 3 | Y4: AUX | AA4: COMP./PESO LONGIT. | AG4: PESO ESTRIBOS | AP4: FERRO | AQ4: BETÃO | AR4: COFRAG.
A5: Pilar | B5: Piso | C5: Altura (m) | D5: b (cm) | E5: h (cm) | F5: Cobr. (cm) | G5: Coef. Transp. (×Ø) | H5: Arranque Inf. (m) | I5: Transp. Sup. (m) | J5: Qtd L1 | K5: Ø L1 (mm) | L5: Qtd L2 | M5: Ø L2 (mm) | N5: Qtd L3 | O5: Ø L3 (mm) | P5: Conj. E1 | Q5: Ø E1 (mm) | R5: Esp.E1 (m) | S5: Conj. E2 | T5: Ø E2 (mm) | U5: Esp.E2 (m) | V5: Conj. E3 | W5: Ø E3 (mm) | X5: Esp.E3 (m) | Y5: Transp. L2 (m) | Z5: Transp. L3 (m) | AA5: Comp. L1 (m) | AB5: Peso L1 (kg) | AC5: Comp. L2 (m) | AD5: Peso L2 (kg) | AE5: Comp. L3 (m) | AF5: Peso L3 (kg) | AG5: C.U. E1 (m) | AH5: Qtd E1 | AI5: Peso E1 (kg) | AJ5: C.U. E2 (m) | AK5: Qtd E2 | AL5: Peso E2 (kg) | AM5: C.U. E3 (m) | AN5: Qtd E3 | AO5: Peso E3 (kg) | AP5: PESO FERRO (kg) | AQ5: Volume Betão (m³) | AR5: Área Cofrag. (m²) | AS5: Observações
A6: P1 | B6: Fundações | C6: =IF(B6<>"",IFERROR(VLOOKUP(B6,PISOS!A:D,4,0),"PENDENTE"),"") -> 0.4 | D6: 30 | E6: 60 | F6: 3 | G6: 50 | H6: =IF(OR(A6="",K6=""),0,G6*K6/1000) -> 0.8 | I6: =IF(OR(A6="",K6="",NOT(ISNUMBER(C6))),0,IF((C6+H6)>12,G6*K6/1000,0)) -> 0 | J6: 6 | K6: 16 | L6: 10 | M6: 12 | P6: 1 | Q6: 8 | R6: 0.2 | S6: 1 | T6: 8 | U6: 0.2 | Y6: =IF(OR(A6="",M6="",NOT(ISNUMBER(C6))),0,IF((C6+H6)>12,G6*M6/1000,0)) -> 0 | Z6: =IF(OR(A6="",O6="",NOT(ISNUMBER(C6))),0,IF((C6+H6)>12,G6*O6/1000,0)) -> 0 | AA6: =IF(OR(A6="",NOT(ISNUMBER(C6))),"",C6+H6+I6) -> 1.2 | AB6: =IF(OR(A6="",AA6=""),0,IFERROR(J6*AA6*VLOOKUP(K6,'TABELA DE PESOS'!$A$2:$B$9,2,FALSE()),0)) -> 11.3616 | AC6: =IF(OR(A6="",NOT(ISNUMBER(C6))),"",C6+H6+Y6) -> 1.2 | AD6: =IF(OR(A6="",AC6=""),0,IFERROR(L6*AC6*VLOOKUP(M6,'TABELA DE PESOS'!$A$2:$B$9,2,FALSE()),0)) -> 10.656 | AE6: =IF(OR(A6="",NOT(ISNUMBER(C6))),"",C6+H6+Z6) -> 1.2 | AF6: =IF(OR(A6="",AE6=""),0,IFERROR(N6*AE6*VLOOKUP(O6,'TABELA DE PESOS'!$A$2:$B$9,2,FALSE()),0)) -> 0 | AG6: =IF(OR(A6="",P6="",NOT(ISNUMBER(C6))),0,P6*(INT(C6/R6)+1)) -> 3 | AH6: =IF(OR(A6="",P6=""),0,2*((D6-2*F6)+(E6-2*F6))/100+2*10*Q6/1000) -> 1.72 | AI6: =IF(OR(A6="",P6=""),0,IFERROR(AG6*AH6*VLOOKUP(Q6,'TABELA DE PESOS'!$A$2:$B$9,2,FALSE()),0)) -> 2.0382 | AJ6: =IF(OR(A6="",S6="",NOT(ISNUMBER(C6))),0,S6*(INT(C6/U6)+1)) -> 3 | AK6: =IF(OR(A6="",S6=""),0,2*((D6-2*F6)+(E6-2*F6))/100+2*10*T6/1000) -> 1.72 | AL6: =IF(OR(A6="",S6=""),0,IFERROR(AJ6*AK6*VLOOKUP(T6,'TABELA DE PESOS'!$A$2:$B$9,2,FALSE()),0)) -> 2.0382 | AM6: =IF(OR(A6="",V6="",NOT(ISNUMBER(C6))),0,V6*(INT(C6/X6)+1)) -> 0 | AN6: =IF(OR(A6="",V6=""),0,2*((D6-2*F6)+(E6-2*F6))/100+2*10*W6/1000) -> 0 | AO6: =IF(OR(A6="",V6=""),0,IFERROR(AM6*AN6*VLOOKUP(W6,'TABELA DE PESOS'!$A$2:$B$9,2,FALSE()),0)) -> 0 | AP6: =IF(A6="",0,AB6+AD6+AF6+AI6+AL6+AO6) -> 26.094 | AQ6: =IF(OR(A6="",NOT(ISNUMBER(C6))),0,(D6/100)*(E6/100)*C6) -> 0.072 | AR6: =IF(OR(A6="",NOT(ISNUMBER(C6))),0,2*(D6/100+E6/100)*C6) -> 0.72
A7: P1 | B7: Piso -1 | C7: =IF(B7<>"",IFERROR(VLOOKUP(B7,PISOS!A:D,4,0),"PENDENTE"),"") -> 3.5 | D7: 30 | E7: 60 | F7: 3 | G7: 50 | H7: =IF(OR(A7="",K7=""),0,G7*K7/1000) -> 0.8 | I7: =IF(OR(A7="",K7="",NOT(ISNUMBER(C7))),0,IF((C7+H7)>12,G7*K7/1000,0)) -> 0 | J7: 6 | K7: 16 | L7: 10 | M7: 12 | P7: 1 | Q7: 8 | R7: 0.2 | S7: 1 | T7: 8 | U7: 0.2 | Y7: =IF(OR(A7="",M7="",NOT(ISNUMBER(C7))),0,IF((C7+H7)>12,G7*M7/1000,0)) -> 0 | Z7: =IF(OR(A7="",O7="",NOT(ISNUMBER(C7))),0,IF((C7+H7)>12,G7*O7/1000,0)) -> 0 | AA7: =IF(OR(A7="",NOT(ISNUMBER(C7))),"",C7+H7+I7) -> 4.3 | AB7: =IF(OR(A7="",AA7=""),0,IFERROR(J7*AA7*VLOOKUP(K7,'TABELA DE PESOS'!$A$2:$B$9,2,FALSE()),0)) -> 40.7124 | AC7: =IF(OR(A7="",NOT(ISNUMBER(C7))),"",C7+H7+Y7) -> 4.3 | AD7: =IF(OR(A7="",AC7=""),0,IFERROR(L7*AC7*VLOOKUP(M7,'TABELA DE PESOS'!$A$2:$B$9,2,FALSE()),0)) -> 38.184 | AE7: =IF(OR(A7="",NOT(ISNUMBER(C7))),"",C7+H7+Z7) -> 4.3 | AF7: =IF(OR(A7="",AE7=""),0,IFERROR(N7*AE7*VLOOKUP(O7,'TABELA DE PESOS'!$A$2:$B$9,2,FALSE()),0)) -> 0 | AG7: =IF(OR(A7="",P7="",NOT(ISNUMBER(C7))),0,P7*(INT(C7/R7)+1)) -> 18 | AH7: =IF(OR(A7="",P7=""),0,2*((D7-2*F7)+(E7-2*F7))/100+2*10*Q7/1000) -> 1.72 | AI7: =IF(OR(A7="",P7=""),0,IFERROR(AG7*AH7*VLOOKUP(Q7,'TABELA DE PESOS'!$A$2:$B$9,2,FALSE()),0)) -> 12.2292 | AJ7: =IF(OR(A7="",S7="",NOT(ISNUMBER(C7))),0,S7*(INT(C7/U7)+1)) -> 18 | AK7: =IF(OR(A7="",S7=""),0,2*((D7-2*F7)+(E7-2*F7))/100+2*10*T7/1000) -> 1.72 | AL7: =IF(OR(A7="",S7=""),0,IFERROR(AJ7*AK7*VLOOKUP(T7,'TABELA DE PESOS'!$A$2:$B$9,2,FALSE()),0)) -> 12.2292 | AM7: =IF(OR(A7="",V7="",NOT(ISNUMBER(C7))),0,V7*(INT(C7/X7)+1)) -> 0 | AN7: =IF(OR(A7="",V7=""),0,2*((D7-2*F7)+(E7-2*F7))/100+2*10*W7/1000) -> 0 | AO7: =IF(OR(A7="",V7=""),0,IFERROR(AM7*AN7*VLOOKUP(W7,'TABELA DE PESOS'!$A$2:$B$9,2,FALSE()),0)) -> 0 | AP7: =IF(A7="",0,AB7+AD7+AF7+AI7+AL7+AO7) -> 103.3548 | AQ7: =IF(OR(A7="",NOT(ISNUMBER(C7))),0,(D7/100)*(E7/100)*C7) -> 0.63 | AR7: =IF(OR(A7="",NOT(ISNUMBER(C7))),0,2*(D7/100+E7/100)*C7) -> 6.3
A8: P2 | B8: Fundações | C8: =IF(B8<>"",IFERROR(VLOOKUP(B8,PISOS!A:D,4,0),"PENDENTE"),"") -> 0.4 | D8: 40 | E8: 70 | F8: 3 | G8: 50 | H8: =IF(OR(A8="",K8=""),0,G8*K8/1000) -> 0.8 | I8: =IF(OR(A8="",K8="",NOT(ISNUMBER(C8))),0,IF((C8+H8)>12,G8*K8/1000,0)) -> 0 | J8: 28 | K8: 16 | P8: 1 | Q8: 8 | R8: 0.2 | S8: 1 | T8: 8 | U8: 0.2 | Y8: =IF(OR(A8="",M8="",NOT(ISNUMBER(C8))),0,IF((C8+H8)>12,G8*M8/1000,0)) -> 0 | Z8: =IF(OR(A8="",O8="",NOT(ISNUMBER(C8))),0,IF((C8+H8)>12,G8*O8/1000,0)) -> 0 | AA8: =IF(OR(A8="",NOT(ISNUMBER(C8))),"",C8+H8+I8) -> 1.2 | AB8: =IF(OR(A8="",AA8=""),0,IFERROR(J8*AA8*VLOOKUP(K8,'TABELA DE PESOS'!$A$2:$B$9,2,FALSE()),0)) -> 53.0208 | AC8: =IF(OR(A8="",NOT(ISNUMBER(C8))),"",C8+H8+Y8) -> 1.2 | AD8: =IF(OR(A8="",AC8=""),0,IFERROR(L8*AC8*VLOOKUP(M8,'TABELA DE PESOS'!$A$2:$B$9,2,FALSE()),0)) -> 0 | AE8: =IF(OR(A8="",NOT(ISNUMBER(C8))),"",C8+H8+Z8) -> 1.2 | AF8: =IF(OR(A8="",AE8=""),0,IFERROR(N8*AE8*VLOOKUP(O8,'TABELA DE PESOS'!$A$2:$B$9,2,FALSE()),0)) -> 0 | AG8: =IF(OR(A8="",P8="",NOT(ISNUMBER(C8))),0,P8*(INT(C8/R8)+1)) -> 3 | AH8: =IF(OR(A8="",P8=""),0,2*((D8-2*F8)+(E8-2*F8))/100+2*10*Q8/1000) -> 2.12 | AI8: =IF(OR(A8="",P8=""),0,IFERROR(AG8*AH8*VLOOKUP(Q8,'TABELA DE PESOS'!$A$2:$B$9,2,FALSE()),0)) -> 2.5122 | AJ8: =IF(OR(A8="",S8="",NOT(ISNUMBER(C8))),0,S8*(INT(C8/U8)+1)) -> 3 | AK8: =IF(OR(A8="",S8=""),0,2*((D8-2*F8)+(E8-2*F8))/100+2*10*T8/1000) -> 2.12 | AL8: =IF(OR(A8="",S8=""),0,IFERROR(AJ8*AK8*VLOOKUP(T8,'TABELA DE PESOS'!$A$2:$B$9,2,FALSE()),0)) -> 2.5122 | AM8: =IF(OR(A8="",V8="",NOT(ISNUMBER(C8))),0,V8*(INT(C8/X8)+1)) -> 0 | AN8: =IF(OR(A8="",V8=""),0,2*((D8-2*F8)+(E8-2*F8))/100+2*10*W8/1000) -> 0 | AO8: =IF(OR(A8="",V8=""),0,IFERROR(AM8*AN8*VLOOKUP(W8,'TABELA DE PESOS'!$A$2:$B$9,2,FALSE()),0)) -> 0 | AP8: =IF(A8="",0,AB8+AD8+AF8+AI8+AL8+AO8) -> 58.0452 | AQ8: =IF(OR(A8="",NOT(ISNUMBER(C8))),0,(D8/100)*(E8/100)*C8) -> 0.112 | AR8: =IF(OR(A8="",NOT(ISNUMBER(C8))),0,2*(D8/100+E8/100)*C8) -> 0.88
A9: P2 | B9: Piso -1 | C9: =IF(B9<>"",IFERROR(VLOOKUP(B9,PISOS!A:D,4,0),"PENDENTE"),"") -> 3.5 | D9: 40 | E9: 70 | F9: 3 | G9: 50 | H9: =IF(OR(A9="",K9=""),0,G9*K9/1000) -> 0.8 | I9: =IF(OR(A9="",K9="",NOT(ISNUMBER(C9))),0,IF((C9+H9)>12,G9*K9/1000,0)) -> 0 | J9: 28 | K9: 16 | P9: 1 | Q9: 8 | R9: 0.2 | S9: 1 | T9: 8 | U9: 0.2 | Y9: =IF(OR(A9="",M9="",NOT(ISNUMBER(C9))),0,IF((C9+H9)>12,G9*M9/1000,0)) -> 0 | Z9: =IF(OR(A9="",O9="",NOT(ISNUMBER(C9))),0,IF((C9+H9)>12,G9*O9/1000,0)) -> 0 | AA9: =IF(OR(A9="",NOT(ISNUMBER(C9))),"",C9+H9+I9) -> 4.3 | AB9: =IF(OR(A9="",AA9=""),0,IFERROR(J9*AA9*VLOOKUP(K9,'TABELA DE PESOS'!$A$2:$B$9,2,FALSE()),0)) -> 189.9912 | AC9: =IF(OR(A9="",NOT(ISNUMBER(C9))),"",C9+H9+Y9) -> 4.3 | AD9: =IF(OR(A9="",AC9=""),0,IFERROR(L9*AC9*VLOOKUP(M9,'TABELA DE PESOS'!$A$2:$B$9,2,FALSE()),0)) -> 0 | AE9: =IF(OR(A9="",NOT(ISNUMBER(C9))),"",C9+H9+Z9) -> 4.3 | AF9: =IF(OR(A9="",AE9=""),0,IFERROR(N9*AE9*VLOOKUP(O9,'TABELA DE PESOS'!$A$2:$B$9,2,FALSE()),0)) -> 0 | AG9: =IF(OR(A9="",P9="",NOT(ISNUMBER(C9))),0,P9*(INT(C9/R9)+1)) -> 18 | AH9: =IF(OR(A9="",P9=""),0,2*((D9-2*F9)+(E9-2*F9))/100+2*10*Q9/1000) -> 2.12 | AI9: =IF(OR(A9="",P9=""),0,IFERROR(AG9*AH9*VLOOKUP(Q9,'TABELA DE PESOS'!$A$2:$B$9,2,FALSE()),0)) -> 15.0732 | AJ9: =IF(OR(A9="",S9="",NOT(ISNUMBER(C9))),0,S9*(INT(C9/U9)+1)) -> 18 | AK9: =IF(OR(A9="",S9=""),0,2*((D9-2*F9)+(E9-2*F9))/100+2*10*T9/1000) -> 2.12 | AL9: =IF(OR(A9="",S9=""),0,IFERROR(AJ9*AK9*VLOOKUP(T9,'TABELA DE PESOS'!$A$2:$B$9,2,FALSE()),0)) -> 15.0732 | AM9: =IF(OR(A9="",V9="",NOT(ISNUMBER(C9))),0,V9*(INT(C9/X9)+1)) -> 0 | AN9: =IF(OR(A9="",V9=""),0,2*((D9-2*F9)+(E9-2*F9))/100+2*10*W9/1000) -> 0 | AO9: =IF(OR(A9="",V9=""),0,IFERROR(AM9*AN9*VLOOKUP(W9,'TABELA DE PESOS'!$A$2:$B$9,2,FALSE()),0)) -> 0 | AP9: =IF(A9="",0,AB9+AD9+AF9+AI9+AL9+AO9) -> 220.1376 | AQ9: =IF(OR(A9="",NOT(ISNUMBER(C9))),0,(D9/100)*(E9/100)*C9) -> 0.98 | AR9: =IF(OR(A9="",NOT(ISNUMBER(C9))),0,2*(D9/100+E9/100)*C9) -> 7.7
A10: P3 | B10: Fundações | C10: =IF(B10<>"",IFERROR(VLOOKUP(B10,PISOS!A:D,4,0),"PENDENTE"),"") -> 0.4 | D10: 40 | E10: 20 | F10: 3 | G10: 50 | H10: =IF(OR(A10="",K10=""),0,G10*K10/1000) -> 0.8 | I10: =IF(OR(A10="",K10="",NOT(ISNUMBER(C10))),0,IF((C10+H10)>12,G10*K10/1000,0)) -> 0 | J10: 6 | K10: 16 | L10: 6 | M10: 12 | P10: 1 | Q10: 8 | R10: 0.2 | Y10: =IF(OR(A10="",M10="",NOT(ISNUMBER(C10))),0,IF((C10+H10)>12,G10*M10/1000,0)) -> 0 | Z10: =IF(OR(A10="",O10="",NOT(ISNUMBER(C10))),0,IF((C10+H10)>12,G10*O10/1000,0)) -> 0 | AA10: =IF(OR(A10="",NOT(ISNUMBER(C10))),"",C10+H10+I10) -> 1.2 | AB10: =IF(OR(A10="",AA10=""),0,IFERROR(J10*AA10*VLOOKUP(K10,'TABELA DE PESOS'!$A$2:$B$9,2,FALSE()),0)) -> 11.3616 | AC10: =IF(OR(A10="",NOT(ISNUMBER(C10))),"",C10+H10+Y10) -> 1.2 | AD10: =IF(OR(A10="",AC10=""),0,IFERROR(L10*AC10*VLOOKUP(M10,'TABELA DE PESOS'!$A$2:$B$9,2,FALSE()),0)) -> 6.3936 | AE10: =IF(OR(A10="",NOT(ISNUMBER(C10))),"",C10+H10+Z10) -> 1.2 | AF10: =IF(OR(A10="",AE10=""),0,IFERROR(N10*AE10*VLOOKUP(O10,'TABELA DE PESOS'!$A$2:$B$9,2,FALSE()),0)) -> 0 | AG10: =IF(OR(A10="",P10="",NOT(ISNUMBER(C10))),0,P10*(INT(C10/R10)+1)) -> 3 | AH10: =IF(OR(A10="",P10=""),0,2*((D10-2*F10)+(E10-2*F10))/100+2*10*Q10/1000) -> 1.12 | AI10: =IF(OR(A10="",P10=""),0,IFERROR(AG10*AH10*VLOOKUP(Q10,'TABELA DE PESOS'!$A$2:$B$9,2,FALSE()),0)) -> 1.3272 | AJ10: =IF(OR(A10="",S10="",NOT(ISNUMBER(C10))),0,S10*(INT(C10/U10)+1)) -> 0 | AK10: =IF(OR(A10="",S10=""),0,2*((D10-2*F10)+(E10-2*F10))/100+2*10*T10/1000) -> 0 | AL10: =IF(OR(A10="",S10=""),0,IFERROR(AJ10*AK10*VLOOKUP(T10,'TABELA DE PESOS'!$A$2:$B$9,2,FALSE()),0)) -> 0 | AM10: =IF(OR(A10="",V10="",NOT(ISNUMBER(C10))),0,V10*(INT(C10/X10)+1)) -> 0 | AN10: =IF(OR(A10="",V10=""),0,2*((D10-2*F10)+(E10-2*F10))/100+2*10*W10/1000) -> 0 | AO10: =IF(OR(A10="",V10=""),0,IFERROR(AM10*AN10*VLOOKUP(W10,'TABELA DE PESOS'!$A$2:$B$9,2,FALSE()),0)) -> 0 | AP10: =IF(A10="",0,AB10+AD10+AF10+AI10+AL10+AO10) -> 19.0824 | AQ10: =IF(OR(A10="",NOT(ISNUMBER(C10))),0,(D10/100)*(E10/100)*C10) -> 0.032 | AR10: =IF(OR(A10="",NOT(ISNUMBER(C10))),0,2*(D10/100+E10/100)*C10) -> 0.48
A11: P3 | B11: Piso -1 | C11: =IF(B11<>"",IFERROR(VLOOKUP(B11,PISOS!A:D,4,0),"PENDENTE"),"") -> 3.5 | D11: 40 | E11: 20 | F11: 3 | G11: 50 | H11: =IF(OR(A11="",K11=""),0,G11*K11/1000) -> 0.8 | I11: =IF(OR(A11="",K11="",NOT(ISNUMBER(C11))),0,IF((C11+H11)>12,G11*K11/1000,0)) -> 0 | J11: 6 | K11: 16 | L11: 6 | M11: 12 | P11: 1 | Q11: 8 | R11: 0.2 | Y11: =IF(OR(A11="",M11="",NOT(ISNUMBER(C11))),0,IF((C11+H11)>12,G11*M11/1000,0)) -> 0 | Z11: =IF(OR(A11="",O11="",NOT(ISNUMBER(C11))),0,IF((C11+H11)>12,G11*O11/1000,0)) -> 0 | AA11: =IF(OR(A11="",NOT(ISNUMBER(C11))),"",C11+H11+I11) -> 4.3 | AB11: =IF(OR(A11="",AA11=""),0,IFERROR(J11*AA11*VLOOKUP(K11,'TABELA DE PESOS'!$A$2:$B$9,2,FALSE()),0)) -> 40.7124 | AC11: =IF(OR(A11="",NOT(ISNUMBER(C11))),"",C11+H11+Y11) -> 4.3 | AD11: =IF(OR(A11="",AC11=""),0,IFERROR(L11*AC11*VLOOKUP(M11,'TABELA DE PESOS'!$A$2:$B$9,2,FALSE()),0)) -> 22.9104 | AE11: =IF(OR(A11="",NOT(ISNUMBER(C11))),"",C11+H11+Z11) -> 4.3 | AF11: =IF(OR(A11="",AE11=""),0,IFERROR(N11*AE11*VLOOKUP(O11,'TABELA DE PESOS'!$A$2:$B$9,2,FALSE()),0)) -> 0 | AG11: =IF(OR(A11="",P11="",NOT(ISNUMBER(C11))),0,P11*(INT(C11/R11)+1)) -> 18 | AH11: =IF(OR(A11="",P11=""),0,2*((D11-2*F11)+(E11-2*F11))/100+2*10*Q11/1000) -> 1.12 | AI11: =IF(OR(A11="",P11=""),0,IFERROR(AG11*AH11*VLOOKUP(Q11,'TABELA DE PESOS'!$A$2:$B$9,2,FALSE()),0)) -> 7.9632 | AJ11: =IF(OR(A11="",S11="",NOT(ISNUMBER(C11))),0,S11*(INT(C11/U11)+1)) -> 0 | AK11: =IF(OR(A11="",S11=""),0,2*((D11-2*F11)+(E11-2*F11))/100+2*10*T11/1000) -> 0 | AL11: =IF(OR(A11="",S11=""),0,IFERROR(AJ11*AK11*VLOOKUP(T11,'TABELA DE PESOS'!$A$2:$B$9,2,FALSE()),0)) -> 0 | AM11: =IF(OR(A11="",V11="",NOT(ISNUMBER(C11))),0,V11*(INT(C11/X11)+1)) -> 0 | AN11: =IF(OR(A11="",V11=""),0,2*((D11-2*F11)+(E11-2*F11))/100+2*10*W11/1000) -> 0 | AO11: =IF(OR(A11="",V11=""),0,IFERROR(AM11*AN11*VLOOKUP(W11,'TABELA DE PESOS'!$A$2:$B$9,2,FALSE()),0)) -> 0 | AP11: =IF(A11="",0,AB11+AD11+AF11+AI11+AL11+AO11) -> 71.586 | AQ11: =IF(OR(A11="",NOT(ISNUMBER(C11))),0,(D11/100)*(E11/100)*C11) -> 0.28 | AR11: =IF(OR(A11="",NOT(ISNUMBER(C11))),0,2*(D11/100+E11/100)*C11) -> 4.2
A12: P7 | B12: Fundações | C12: =IF(B12<>"",IFERROR(VLOOKUP(B12,PISOS!A:D,4,0),"PENDENTE"),"") -> 0.4 | D12: 50 | E12: 30 | F12: 3 | G12: 50 | H12: =IF(OR(A12="",K12=""),0,G12*K12/1000) -> 0.8 | I12: =IF(OR(A12="",K12="",NOT(ISNUMBER(C12))),0,IF((C12+H12)>12,G12*K12/1000,0)) -> 0 | J12: 10 | K12: 16 | P12: 1 | Q12: 8 | R12: 0.2 | Y12: =IF(OR(A12="",M12="",NOT(ISNUMBER(C12))),0,IF((C12+H12)>12,G12*M12/1000,0)) -> 0 | Z12: =IF(OR(A12="",O12="",NOT(ISNUMBER(C12))),0,IF((C12+H12)>12,G12*O12/1000,0)) -> 0 | AA12: =IF(OR(A12="",NOT(ISNUMBER(C12))),"",C12+H12+I12) -> 1.2 | AB12: =IF(OR(A12="",AA12=""),0,IFERROR(J12*AA12*VLOOKUP(K12,'TABELA DE PESOS'!$A$2:$B$9,2,FALSE()),0)) -> 18.936 | AC12: =IF(OR(A12="",NOT(ISNUMBER(C12))),"",C12+H12+Y12) -> 1.2 | AD12: =IF(OR(A12="",AC12=""),0,IFERROR(L12*AC12*VLOOKUP(M12,'TABELA DE PESOS'!$A$2:$B$9,2,FALSE()),0)) -> 0 | AE12: =IF(OR(A12="",NOT(ISNUMBER(C12))),"",C12+H12+Z12) -> 1.2 | AF12: =IF(OR(A12="",AE12=""),0,IFERROR(N12*AE12*VLOOKUP(O12,'TABELA DE PESOS'!$A$2:$B$9,2,FALSE()),0)) -> 0 | AG12: =IF(OR(A12="",P12="",NOT(ISNUMBER(C12))),0,P12*(INT(C12/R12)+1)) -> 3 | AH12: =IF(OR(A12="",P12=""),0,2*((D12-2*F12)+(E12-2*F12))/100+2*10*Q12/1000) -> 1.52 | AI12: =IF(OR(A12="",P12=""),0,IFERROR(AG12*AH12*VLOOKUP(Q12,'TABELA DE PESOS'!$A$2:$B$9,2,FALSE()),0)) -> 1.8012 | AJ12: =IF(OR(A12="",S12="",NOT(ISNUMBER(C12))),0,S12*(INT(C12/U12)+1)) -> 0 | AK12: =IF(OR(A12="",S12=""),0,2*((D12-2*F12)+(E12-2*F12))/100+2*10*T12/1000) -> 0 | AL12: =IF(OR(A12="",S12=""),0,IFERROR(AJ12*AK12*VLOOKUP(T12,'TABELA DE PESOS'!$A$2:$B$9,2,FALSE()),0)) -> 0 | AM12: =IF(OR(A12="",V12="",NOT(ISNUMBER(C12))),0,V12*(INT(C12/X12)+1)) -> 0 | AN12: =IF(OR(A12="",V12=""),0,2*((D12-2*F12)+(E12-2*F12))/100+2*10*W12/1000) -> 0 | AO12: =IF(OR(A12="",V12=""),0,IFERROR(AM12*AN12*VLOOKUP(W12,'TABELA DE PESOS'!$A$2:$B$9,2,FALSE()),0)) -> 0 | AP12: =IF(A12="",0,AB12+AD12+AF12+AI12+AL12+AO12) -> 20.7372 | AQ12: =IF(OR(A12="",NOT(ISNUMBER(C12))),0,(D12/100)*(E12/100)*C12) -> 0.06 | AR12: =IF(OR(A12="",NOT(ISNUMBER(C12))),0,2*(D12/100+E12/100)*C12) -> 0.64
A13: P7 | B13: Piso -1 | C13: =IF(B13<>"",IFERROR(VLOOKUP(B13,PISOS!A:D,4,0),"PENDENTE"),"") -> 3.5 | D13: 50 | E13: 30 | F13: 3 | G13: 50 | H13: =IF(OR(A13="",K13=""),0,G13*K13/1000) -> 0.8 | I13: =IF(OR(A13="",K13="",NOT(ISNUMBER(C13))),0,IF((C13+H13)>12,G13*K13/1000,0)) -> 0 | J13: 7 | K13: 16 | P13: 1 | Q13: 8 | R13: 0.2 | Y13: =IF(OR(A13="",M13="",NOT(ISNUMBER(C13))),0,IF((C13+H13)>12,G13*M13/1000,0)) -> 0 | Z13: =IF(OR(A13="",O13="",NOT(ISNUMBER(C13))),0,IF((C13+H13)>12,G13*O13/1000,0)) -> 0 | AA13: =IF(OR(A13="",NOT(ISNUMBER(C13))),"",C13+H13+I13) -> 4.3 | AB13: =IF(OR(A13="",AA13=""),0,IFERROR(J13*AA13*VLOOKUP(K13,'TABELA DE PESOS'!$A$2:$B$9,2,FALSE()),0)) -> 47.4978 | AC13: =IF(OR(A13="",NOT(ISNUMBER(C13))),"",C13+H13+Y13) -> 4.3 | AD13: =IF(OR(A13="",AC13=""),0,IFERROR(L13*AC13*VLOOKUP(M13,'TABELA DE PESOS'!$A$2:$B$9,2,FALSE()),0)) -> 0 | AE13: =IF(OR(A13="",NOT(ISNUMBER(C13))),"",C13+H13+Z13) -> 4.3 | AF13: =IF(OR(A13="",AE13=""),0,IFERROR(N13*AE13*VLOOKUP(O13,'TABELA DE PESOS'!$A$2:$B$9,2,FALSE()),0)) -> 0 | AG13: =IF(OR(A13="",P13="",NOT(ISNUMBER(C13))),0,P13*(INT(C13/R13)+1)) -> 18 | AH13: =IF(OR(A13="",P13=""),0,PI()*(D13-2*F13)/100+2*10*Q13/1000) -> 1.5423008 | AI13: =IF(OR(A13="",P13=""),0,IFERROR(AG13*AH13*VLOOKUP(Q13,'TABELA DE PESOS'!$A$2:$B$9,2,FALSE()),0)) -> 10.965758 | AJ13: =IF(OR(A13="",S13="",NOT(ISNUMBER(C13))),0,S13*(INT(C13/U13)+1)) -> 0 | AK13: =IF(OR(A13="",S13=""),0,PI()*(D13-2*F13)/100+2*10*T13/1000) -> 0 | AL13: =IF(OR(A13="",S13=""),0,IFERROR(AJ13*AK13*VLOOKUP(T13,'TABELA DE PESOS'!$A$2:$B$9,2,FALSE()),0)) -> 0 | AM13: =IF(OR(A13="",V13="",NOT(ISNUMBER(C13))),0,V13*(INT(C13/X13)+1)) -> 0 | AN13: =IF(OR(A13="",V13=""),0,PI()*(D13-2*F13)/100+2*10*W13/1000) -> 0 | AO13: =IF(OR(A13="",V13=""),0,IFERROR(AM13*AN13*VLOOKUP(W13,'TABELA DE PESOS'!$A$2:$B$9,2,FALSE()),0)) -> 0 | AP13: =IF(A13="",0,AB13+AD13+AF13+AI13+AL13+AO13) -> 58.463558 | AQ13: =IF(OR(A13="",NOT(ISNUMBER(C13))),0,PI()*(D13/200)^2*C13) -> 0.68722339 | AR13: =IF(OR(A13="",NOT(ISNUMBER(C13))),0,PI()*(D13/100)*C13) -> 5.4977871
G14: 50 | H14: =IF(OR(A14="",K14=""),0,G14*K14/1000) -> 0 | I14: =IF(OR(A14="",K14="",NOT(ISNUMBER(C14))),0,IF((C14+H14)>12,G14*K14/1000,0)) -> 0 | Y14: =IF(OR(A14="",M14="",NOT(ISNUMBER(C14))),0,IF((C14+H14)>12,G14*M14/1000,0)) -> 0 | Z14: =IF(OR(A14="",O14="",NOT(ISNUMBER(C14))),0,IF((C14+H14)>12,G14*O14/1000,0)) -> 0 | AA14: =IF(OR(A14="",NOT(ISNUMBER(C14))),"",C14+H14+I14) | AB14: =IF(OR(A14="",AA14=""),0,IFERROR(J14*AA14*VLOOKUP(K14,'TABELA DE PESOS'!$A$2:$B$9,2,FALSE()),0)) -> 0 | AC14: =IF(OR(A14="",NOT(ISNUMBER(C14))),"",C14+H14+Y14) | AD14: =IF(OR(A14="",AC14=""),0,IFERROR(L14*AC14*VLOOKUP(M14,'TABELA DE PESOS'!$A$2:$B$9,2,FALSE()),0)) -> 0 | AE14: =IF(OR(A14="",NOT(ISNUMBER(C14))),"",C14+H14+Z14) | AF14: =IF(OR(A14="",AE14=""),0,IFERROR(N14*AE14*VLOOKUP(O14,'TABELA DE PESOS'!$A$2:$B$9,2,FALSE()),0)) -> 0 | AG14: =IF(OR(A14="",P14="",NOT(ISNUMBER(C14))),0,P14*(INT(C14/R14)+1)) -> 0 | AH14: =IF(OR(A14="",P14=""),0,2*((D14-2*F14)+(E14-2*F14))/100+2*10*Q14/1000) -> 0 | AI14: =IF(OR(A14="",P14=""),0,IFERROR(AG14*AH14*VLOOKUP(Q14,'TABELA DE PESOS'!$A$2:$B$9,2,FALSE()),0)) -> 0 | AJ14: =IF(OR(A14="",S14="",NOT(ISNUMBER(C14))),0,S14*(INT(C14/U14)+1)) -> 0 | AK14: =IF(OR(A14="",S14=""),0,2*((D14-2*F14)+(E14-2*F14))/100+2*10*T14/1000) -> 0 | AL14: =IF(OR(A14="",S14=""),0,IFERROR(AJ14*AK14*VLOOKUP(T14,'TABELA DE PESOS'!$A$2:$B$9,2,FALSE()),0)) -> 0 | AM14: =IF(OR(A14="",V14="",NOT(ISNUMBER(C14))),0,V14*(INT(C14/X14)+1)) -> 0 | AN14: =IF(OR(A14="",V14=""),0,2*((D14-2*F14)+(E14-2*F14))/100+2*10*W14/1000) -> 0 | AO14: =IF(OR(A14="",V14=""),0,IFERROR(AM14*AN14*VLOOKUP(W14,'TABELA DE PESOS'!$A$2:$B$9,2,FALSE()),0)) -> 0 | AP14: =IF(A14="",0,AB14+AD14+AF14+AI14+AL14+AO14) -> 0 | AQ14: =IF(OR(A14="",NOT(ISNUMBER(C14))),0,(D14/100)*(E14/100)*C14) -> 0 | AR14: =IF(OR(A14="",NOT(ISNUMBER(C14))),0,2*(D14/100+E14/100)*C14) -> 0
A15: TOTAL GERAL | AB15: =SUM(AB6:AB14) -> 413.5938 | AD15: =SUM(AD6:AD14) -> 78.144 | AF15: =SUM(AF6:AF14) -> 0 | AI15: =SUM(AI6:AI14) -> 53.910158 | AL15: =SUM(AL6:AL14) -> 31.8528 | AO15: =SUM(AO6:AO14) -> 0 | AP15: =SUM(AP6:AP14) -> 577.50076 | AQ15: =SUM(AQ6:AQ14) -> 2.8532234 | AR15: =SUM(AR6:AR14) -> 26.417787

Sheet PILARES
A1: LEVANTAMENTO DE AÇO — PILARES
A2: Azul=entrada | Bege=transpasse | Verde=calculado | Laranja=ferro total | Roxo=betão | Amarelo=cofragem
A4: GEOMETRIA / SEÇÃO | G4: TRANSPASSE / ARRANQUE | J4: ARM. LONGITUDINAL | P4: EST. TIPO 1 | S4: EST. TIPO 2 | V4: EST. TIPO 3 | Y4: AUX | AA4: COMP./PESO LONGIT. | AG4: PESO ESTRIBOS | AP4: FERRO | AQ4: BETÃO | AR4: COFRAG.
A5: Pilar | B5: Piso | C5: Altura (m) | D5: b (cm) | E5: h (cm) | F5: Cobr. (cm) | G5: Coef. Transp. (×Ø) | H5: Arranque Inf. (m) | I5: Transp. Sup. (m) | J5: Qtd L1 | K5: Ø L1 (mm) | L5: Qtd L2 | M5: Ø L2 (mm) | N5: Qtd L3 | O5: Ø L3 (mm) | P5: Conj. E1 | Q5: Ø E1 (mm) | R5: Esp.E1 (m) | S5: Conj. E2 | T5: Ø E2 (mm) | U5: Esp.E2 (m) | V5: Conj. E3 | W5: Ø E3 (mm) | X5: Esp.E3 (m) | Y5: Transp. L2 (m) | Z5: Transp. L3 (m) | AA5: Comp. L1 (m) | AB5: Peso L1 (kg) | AC5: Comp. L2 (m) | AD5: Peso L2 (kg) | AE5: Comp. L3 (m) | AF5: Peso L3 (kg) | AG5: C.U. E1 (m) | AH5: Qtd E1 | AI5: Peso E1 (kg) | AJ5: C.U. E2 (m) | AK5: Qtd E2 | AL5: Peso E2 (kg) | AM5: C.U. E3 (m) | AN5: Qtd E3 | AO5: Peso E3 (kg) | AP5: PESO FERRO (kg) | AQ5: Volume Betão (m³) | AR5: Área Cofrag. (m²) | AS5: Observações
A6: P1-P0 | B6: Piso 0 | C6: =IF(B6<>"",IFERROR(VLOOKUP(B6,PISOS!A:D,4,0),"PENDENTE"),"") -> PENDENTE | D6: 30 | E6: 60 | F6: 3 | G6: 50 | H6: =IF(OR(A6="",K6=""),0,G6*K6/1000) -> 0.8 | I6: =IF(OR(A6="",K6="",NOT(ISNUMBER(C6))),0,IF((C6+H6)>12,G6*K6/1000,0)) -> 0 | J6: 6 | K6: 16 | L6: 10 | M6: 12 | P6: 1 | Q6: 8 | R6: 0.2 | S6: 1 | T6: 8 | U6: 0.2 | Y6: =IF(OR(A6="",M6="",NOT(ISNUMBER(C6))),0,IF((C6+H6)>12,G6*M6/1000,0)) -> 0 | Z6: =IF(OR(A6="",O6="",NOT(ISNUMBER(C6))),0,IF((C6+H6)>12,G6*O6/1000,0)) -> 0 | AA6: =IF(OR(A6="",NOT(ISNUMBER(C6))),"",C6+H6+I6) | AB6: =IF(OR(A6="",AA6=""),0,IFERROR(J6*AA6*VLOOKUP(K6,'TABELA DE PESOS'!$A$2:$B$9,2,FALSE()),0)) -> 0 | AC6: =IF(OR(A6="",NOT(ISNUMBER(C6))),"",C6+H6+Y6) | AD6: =IF(OR(A6="",AC6=""),0,IFERROR(L6*AC6*VLOOKUP(M6,'TABELA DE PESOS'!$A$2:$B$9,2,FALSE()),0)) -> 0 | AE6: =IF(OR(A6="",NOT(ISNUMBER(C6))),"",C6+H6+Z6) | AF6: =IF(OR(A6="",AE6=""),0,IFERROR(N6*AE6*VLOOKUP(O6,'TABELA DE PESOS'!$A$2:$B$9,2,FALSE()),0)) -> 0 | AG6: =IF(OR(A6="",P6="",NOT(ISNUMBER(C6))),0,P6*(INT(C6/R6)+1)) -> 0 | AH6: =IF(OR(A6="",P6=""),0,2*((D6-2*F6)+(E6-2*F6))/100+2*10*Q6/1000) -> 1.72 | AI6: =IF(OR(A6="",P6=""),0,IFERROR(AG6*AH6*VLOOKUP(Q6,'TABELA DE PESOS'!$A$2:$B$9,2,FALSE()),0)) -> 0 | AJ6: =IF(OR(A6="",S6="",NOT(ISNUMBER(C6))),0,S6*(INT(C6/U6)+1)) -> 0 | AK6: =IF(OR(A6="",S6=""),0,2*((D6-2*F6)+(E6-2*F6))/100+2*10*T6/1000) -> 1.72 | AL6: =IF(OR(A6="",S6=""),0,IFERROR(AJ6*AK6*VLOOKUP(T6,'TABELA DE PESOS'!$A$2:$B$9,2,FALSE()),0)) -> 0 | AM6: =IF(OR(A6="",V6="",NOT(ISNUMBER(C6))),0,V6*(INT(C6/X6)+1)) -> 0 | AN6: =IF(OR(A6="",V6=""),0,2*((D6-2*F6)+(E6-2*F6))/100+2*10*W6/1000) -> 0 | AO6: =IF(OR(A6="",V6=""),0,IFERROR(AM6*AN6*VLOOKUP(W6,'TABELA DE PESOS'!$A$2:$B$9,2,FALSE()),0)) -> 0 | AP6: =IF(A6="",0,AB6+AD6+AF6+AI6+AL6+AO6) -> 0 | AQ6: =IF(OR(A6="",NOT(ISNUMBER(C6))),0,(D6/100)*(E6/100)*C6) -> 0 | AR6: =IF(OR(A6="",NOT(ISNUMBER(C6))),0,2*(D6/100+E6/100)*C6) -> 0 | AS6: Fundações a Piso 0. Cinta exterior e cinta interior fechada. Contagem cintas exige zonas a/2.
A7: P1-P1 | B7: Piso 1 | C7: =IF(B7<>"",IFERROR(VLOOKUP(B7,PISOS!A:D,4,0),"PENDENTE"),"") -> 3.93 | D7: 30 | E7: 60 | F7: 3 | G7: 50 | H7: =IF(OR(A7="",K7=""),0,G7*K7/1000) -> 0.8 | I7: =IF(OR(A7="",K7="",NOT(ISNUMBER(C7))),0,IF((C7+H7)>12,G7*K7/1000,0)) -> 0 | J7: 6 | K7: 16 | L7: 10 | M7: 12 | P7: 1 | Q7: 8 | R7: 0.2 | S7: 1 | T7: 8 | U7: 0.2 | Y7: =IF(OR(A7="",M7="",NOT(ISNUMBER(C7))),0,IF((C7+H7)>12,G7*M7/1000,0)) -> 0 | Z7: =IF(OR(A7="",O7="",NOT(ISNUMBER(C7))),0,IF((C7+H7)>12,G7*O7/1000,0)) -> 0 | AA7: =IF(OR(A7="",NOT(ISNUMBER(C7))),"",C7+H7+I7) -> 4.73 | AB7: =IF(OR(A7="",AA7=""),0,IFERROR(J7*AA7*VLOOKUP(K7,'TABELA DE PESOS'!$A$2:$B$9,2,FALSE()),0)) -> 44.78364 | AC7: =IF(OR(A7="",NOT(ISNUMBER(C7))),"",C7+H7+Y7) -> 4.73 | AD7: =IF(OR(A7="",AC7=""),0,IFERROR(L7*AC7*VLOOKUP(M7,'TABELA DE PESOS'!$A$2:$B$9,2,FALSE()),0)) -> 42.0024 | AE7: =IF(OR(A7="",NOT(ISNUMBER(C7))),"",C7+H7+Z7) -> 4.73 | AF7: =IF(OR(A7="",AE7=""),0,IFERROR(N7*AE7*VLOOKUP(O7,'TABELA DE PESOS'!$A$2:$B$9,2,FALSE()),0)) -> 0 | AG7: =IF(OR(A7="",P7="",NOT(ISNUMBER(C7))),0,P7*(INT(C7/R7)+1)) -> 20 | AH7: =IF(OR(A7="",P7=""),0,2*((D7-2*F7)+(E7-2*F7))/100+2*10*Q7/1000) -> 1.72 | AI7: =IF(OR(A7="",P7=""),0,IFERROR(AG7*AH7*VLOOKUP(Q7,'TABELA DE PESOS'!$A$2:$B$9,2,FALSE()),0)) -> 13.588 | AJ7: =IF(OR(A7="",S7="",NOT(ISNUMBER(C7))),0,S7*(INT(C7/U7)+1)) -> 20 | AK7: =IF(OR(A7="",S7=""),0,2*((D7-2*F7)+(E7-2*F7))/100+2*10*T7/1000) -> 1.72 | AL7: =IF(OR(A7="",S7=""),0,IFERROR(AJ7*AK7*VLOOKUP(T7,'TABELA DE PESOS'!$A$2:$B$9,2,FALSE()),0)) -> 13.588 | AM7: =IF(OR(A7="",V7="",NOT(ISNUMBER(C7))),0,V7*(INT(C7/X7)+1)) -> 0 | AN7: =IF(OR(A7="",V7=""),0,2*((D7-2*F7)+(E7-2*F7))/100+2*10*W7/1000) -> 0 | AO7: =IF(OR(A7="",V7=""),0,IFERROR(AM7*AN7*VLOOKUP(W7,'TABELA DE PESOS'!$A$2:$B$9,2,FALSE()),0)) -> 0 | AP7: =IF(A7="",0,AB7+AD7+AF7+AI7+AL7+AO7) -> 113.96204 | AQ7: =IF(OR(A7="",NOT(ISNUMBER(C7))),0,(D7/100)*(E7/100)*C7) -> 0.7074 | AR7: =IF(OR(A7="",NOT(ISNUMBER(C7))),0,2*(D7/100+E7/100)*C7) -> 7.074 | AS7: Piso 0 a Piso 1. Cinta exterior e cinta interior fechada. Contagem cintas exige zonas a/2.
A8: P1-COB | B8: Cobertura | C8: =IF(B8<>"",IFERROR(VLOOKUP(B8,PISOS!A:D,4,0),"PENDENTE"),"") -> PENDENTE | D8: 30 | E8: 60 | F8: 3 | G8: 50 | H8: =IF(OR(A8="",K8=""),0,G8*K8/1000) -> 0.8 | I8: =IF(OR(A8="",K8="",NOT(ISNUMBER(C8))),0,IF((C8+H8)>12,G8*K8/1000,0)) -> 0 | J8: 6 | K8: 16 | L8: 10 | M8: 12 | P8: 1 | Q8: 8 | R8: 0.2 | S8: 1 | T8: 8 | U8: 0.2 | Y8: =IF(OR(A8="",M8="",NOT(ISNUMBER(C8))),0,IF((C8+H8)>12,G8*M8/1000,0)) -> 0 | Z8: =IF(OR(A8="",O8="",NOT(ISNUMBER(C8))),0,IF((C8+H8)>12,G8*O8/1000,0)) -> 0 | AA8: =IF(OR(A8="",NOT(ISNUMBER(C8))),"",C8+H8+I8) | AB8: =IF(OR(A8="",AA8=""),0,IFERROR(J8*AA8*VLOOKUP(K8,'TABELA DE PESOS'!$A$2:$B$9,2,FALSE()),0)) -> 0 | AC8: =IF(OR(A8="",NOT(ISNUMBER(C8))),"",C8+H8+Y8) | AD8: =IF(OR(A8="",AC8=""),0,IFERROR(L8*AC8*VLOOKUP(M8,'TABELA DE PESOS'!$A$2:$B$9,2,FALSE()),0)) -> 0 | AE8: =IF(OR(A8="",NOT(ISNUMBER(C8))),"",C8+H8+Z8) | AF8: =IF(OR(A8="",AE8=""),0,IFERROR(N8*AE8*VLOOKUP(O8,'TABELA DE PESOS'!$A$2:$B$9,2,FALSE()),0)) -> 0 | AG8: =IF(OR(A8="",P8="",NOT(ISNUMBER(C8))),0,P8*(INT(C8/R8)+1)) -> 0 | AH8: =IF(OR(A8="",P8=""),0,2*((D8-2*F8)+(E8-2*F8))/100+2*10*Q8/1000) -> 1.72 | AI8: =IF(OR(A8="",P8=""),0,IFERROR(AG8*AH8*VLOOKUP(Q8,'TABELA DE PESOS'!$A$2:$B$9,2,FALSE()),0)) -> 0 | AJ8: =IF(OR(A8="",S8="",NOT(ISNUMBER(C8))),0,S8*(INT(C8/U8)+1)) -> 0 | AK8: =IF(OR(A8="",S8=""),0,2*((D8-2*F8)+(E8-2*F8))/100+2*10*T8/1000) -> 1.72 | AL8: =IF(OR(A8="",S8=""),0,IFERROR(AJ8*AK8*VLOOKUP(T8,'TABELA DE PESOS'!$A$2:$B$9,2,FALSE()),0)) -> 0 | AM8: =IF(OR(A8="",V8="",NOT(ISNUMBER(C8))),0,V8*(INT(C8/X8)+1)) -> 0 | AN8: =IF(OR(A8="",V8=""),0,2*((D8-2*F8)+(E8-2*F8))/100+2*10*W8/1000) -> 0 | AO8: =IF(OR(A8="",V8=""),0,IFERROR(AM8*AN8*VLOOKUP(W8,'TABELA DE PESOS'!$A$2:$B$9,2,FALSE()),0)) -> 0 | AP8: =IF(A8="",0,AB8+AD8+AF8+AI8+AL8+AO8) -> 0 | AQ8: =IF(OR(A8="",NOT(ISNUMBER(C8))),0,(D8/100)*(E8/100)*C8) -> 0 | AR8: =IF(OR(A8="",NOT(ISNUMBER(C8))),0,2*(D8/100+E8/100)*C8) -> 0 | AS8: Piso 1 a Cobertura. Cinta exterior e cinta interior fechada. Contagem cintas exige zonas a/2.
A9: P2-P0 | B9: Piso 0 | C9: =IF(B9<>"",IFERROR(VLOOKUP(B9,PISOS!A:D,4,0),"PENDENTE"),"") -> PENDENTE | D9: 40 | E9: 70 | F9: 3 | G9: 50 | H9: =IF(OR(A9="",K9=""),0,G9*K9/1000) -> 0.8 | I9: =IF(OR(A9="",K9="",NOT(ISNUMBER(C9))),0,IF((C9+H9)>12,G9*K9/1000,0)) -> 0 | J9: 28 | K9: 16 | P9: 1 | Q9: 8 | R9: 0.2 | S9: 1 | T9: 8 | U9: 0.2 | Y9: =IF(OR(A9="",M9="",NOT(ISNUMBER(C9))),0,IF((C9+H9)>12,G9*M9/1000,0)) -> 0 | Z9: =IF(OR(A9="",O9="",NOT(ISNUMBER(C9))),0,IF((C9+H9)>12,G9*O9/1000,0)) -> 0 | AA9: =IF(OR(A9="",NOT(ISNUMBER(C9))),"",C9+H9+I9) | AB9: =IF(OR(A9="",AA9=""),0,IFERROR(J9*AA9*VLOOKUP(K9,'TABELA DE PESOS'!$A$2:$B$9,2,FALSE()),0)) -> 0 | AC9: =IF(OR(A9="",NOT(ISNUMBER(C9))),"",C9+H9+Y9) | AD9: =IF(OR(A9="",AC9=""),0,IFERROR(L9*AC9*VLOOKUP(M9,'TABELA DE PESOS'!$A$2:$B$9,2,FALSE()),0)) -> 0 | AE9: =IF(OR(A9="",NOT(ISNUMBER(C9))),"",C9+H9+Z9) | AF9: =IF(OR(A9="",AE9=""),0,IFERROR(N9*AE9*VLOOKUP(O9,'TABELA DE PESOS'!$A$2:$B$9,2,FALSE()),0)) -> 0 | AG9: =IF(OR(A9="",P9="",NOT(ISNUMBER(C9))),0,P9*(INT(C9/R9)+1)) -> 0 | AH9: =IF(OR(A9="",P9=""),0,2*((D9-2*F9)+(E9-2*F9))/100+2*10*Q9/1000) -> 2.12 | AI9: =IF(OR(A9="",P9=""),0,IFERROR(AG9*AH9*VLOOKUP(Q9,'TABELA DE PESOS'!$A$2:$B$9,2,FALSE()),0)) -> 0 | AJ9: =IF(OR(A9="",S9="",NOT(ISNUMBER(C9))),0,S9*(INT(C9/U9)+1)) -> 0 | AK9: =IF(OR(A9="",S9=""),0,2*((D9-2*F9)+(E9-2*F9))/100+2*10*T9/1000) -> 2.12 | AL9: =IF(OR(A9="",S9=""),0,IFERROR(AJ9*AK9*VLOOKUP(T9,'TABELA DE PESOS'!$A$2:$B$9,2,FALSE()),0)) -> 0 | AM9: =IF(OR(A9="",V9="",NOT(ISNUMBER(C9))),0,V9*(INT(C9/X9)+1)) -> 0 | AN9: =IF(OR(A9="",V9=""),0,2*((D9-2*F9)+(E9-2*F9))/100+2*10*W9/1000) -> 0 | AO9: =IF(OR(A9="",V9=""),0,IFERROR(AM9*AN9*VLOOKUP(W9,'TABELA DE PESOS'!$A$2:$B$9,2,FALSE()),0)) -> 0 | AP9: =IF(A9="",0,AB9+AD9+AF9+AI9+AL9+AO9) -> 0 | AQ9: =IF(OR(A9="",NOT(ISNUMBER(C9))),0,(D9/100)*(E9/100)*C9) -> 0 | AR9: =IF(OR(A9="",NOT(ISNUMBER(C9))),0,2*(D9/100+E9/100)*C9) -> 0 | AS9: Fundações a Piso 0. Cinta exterior e cinta interior fechada. Contagem cintas exige zonas a/2.
A10: P2-P1 | B10: Piso 1 | C10: =IF(B10<>"",IFERROR(VLOOKUP(B10,PISOS!A:D,4,0),"PENDENTE"),"") -> 3.93 | D10: 40 | E10: 70 | F10: 3 | G10: 50 | H10: =IF(OR(A10="",K10=""),0,G10*K10/1000) -> 0.8 | I10: =IF(OR(A10="",K10="",NOT(ISNUMBER(C10))),0,IF((C10+H10)>12,G10*K10/1000,0)) -> 0 | J10: 28 | K10: 16 | P10: 1 | Q10: 8 | R10: 0.2 | S10: 1 | T10: 8 | U10: 0.2 | Y10: =IF(OR(A10="",M10="",NOT(ISNUMBER(C10))),0,IF((C10+H10)>12,G10*M10/1000,0)) -> 0 | Z10: =IF(OR(A10="",O10="",NOT(ISNUMBER(C10))),0,IF((C10+H10)>12,G10*O10/1000,0)) -> 0 | AA10: =IF(OR(A10="",NOT(ISNUMBER(C10))),"",C10+H10+I10) -> 4.73 | AB10: =IF(OR(A10="",AA10=""),0,IFERROR(J10*AA10*VLOOKUP(K10,'TABELA DE PESOS'!$A$2:$B$9,2,FALSE()),0)) -> 208.99032 | AC10: =IF(OR(A10="",NOT(ISNUMBER(C10))),"",C10+H10+Y10) -> 4.73 | AD10: =IF(OR(A10="",AC10=""),0,IFERROR(L10*AC10*VLOOKUP(M10,'TABELA DE PESOS'!$A$2:$B$9,2,FALSE()),0)) -> 0 | AE10: =IF(OR(A10="",NOT(ISNUMBER(C10))),"",C10+H10+Z10) -> 4.73 | AF10: =IF(OR(A10="",AE10=""),0,IFERROR(N10*AE10*VLOOKUP(O10,'TABELA DE PESOS'!$A$2:$B$9,2,FALSE()),0)) -> 0 | AG10: =IF(OR(A10="",P10="",NOT(ISNUMBER(C10))),0,P10*(INT(C10/R10)+1)) -> 20 | AH10: =IF(OR(A10="",P10=""),0,2*((D10-2*F10)+(E10-2*F10))/100+2*10*Q10/1000) -> 2.12 | AI10: =IF(OR(A10="",P10=""),0,IFERROR(AG10*AH10*VLOOKUP(Q10,'TABELA DE PESOS'!$A$2:$B$9,2,FALSE()),0)) -> 16.748 | AJ10: =IF(OR(A10="",S10="",NOT(ISNUMBER(C10))),0,S10*(INT(C10/U10)+1)) -> 20 | AK10: =IF(OR(A10="",S10=""),0,2*((D10-2*F10)+(E10-2*F10))/100+2*10*T10/1000) -> 2.12 | AL10: =IF(OR(A10="",S10=""),0,IFERROR(AJ10*AK10*VLOOKUP(T10,'TABELA DE PESOS'!$A$2:$B$9,2,FALSE()),0)) -> 16.748 | AM10: =IF(OR(A10="",V10="",NOT(ISNUMBER(C10))),0,V10*(INT(C10/X10)+1)) -> 0 | AN10: =IF(OR(A10="",V10=""),0,2*((D10-2*F10)+(E10-2*F10))/100+2*10*W10/1000) -> 0 | AO10: =IF(OR(A10="",V10=""),0,IFERROR(AM10*AN10*VLOOKUP(W10,'TABELA DE PESOS'!$A$2:$B$9,2,FALSE()),0)) -> 0 | AP10: =IF(A10="",0,AB10+AD10+AF10+AI10+AL10+AO10) -> 242.48632 | AQ10: =IF(OR(A10="",NOT(ISNUMBER(C10))),0,(D10/100)*(E10/100)*C10) -> 1.1004 | AR10: =IF(OR(A10="",NOT(ISNUMBER(C10))),0,2*(D10/100+E10/100)*C10) -> 8.646 | AS10: Piso 0 a Piso 1. Cinta exterior e cinta interior fechada. Contagem cintas exige zonas a/2.
A11: P3-P0 | B11: Piso 0 | C11: =IF(B11<>"",IFERROR(VLOOKUP(B11,PISOS!A:D,4,0),"PENDENTE"),"") -> PENDENTE | D11: 40 | E11: 20 | F11: 3 | G11: 50 | H11: =IF(OR(A11="",K11=""),0,G11*K11/1000) -> 0.8 | I11: =IF(OR(A11="",K11="",NOT(ISNUMBER(C11))),0,IF((C11+H11)>12,G11*K11/1000,0)) -> 0 | J11: 6 | K11: 16 | L11: 6 | M11: 12 | P11: 1 | Q11: 8 | R11: 0.2 | Y11: =IF(OR(A11="",M11="",NOT(ISNUMBER(C11))),0,IF((C11+H11)>12,G11*M11/1000,0)) -> 0 | Z11: =IF(OR(A11="",O11="",NOT(ISNUMBER(C11))),0,IF((C11+H11)>12,G11*O11/1000,0)) -> 0 | AA11: =IF(OR(A11="",NOT(ISNUMBER(C11))),"",C11+H11+I11) | AB11: =IF(OR(A11="",AA11=""),0,IFERROR(J11*AA11*VLOOKUP(K11,'TABELA DE PESOS'!$A$2:$B$9,2,FALSE()),0)) -> 0 | AC11: =IF(OR(A11="",NOT(ISNUMBER(C11))),"",C11+H11+Y11) | AD11: =IF(OR(A11="",AC11=""),0,IFERROR(L11*AC11*VLOOKUP(M11,'TABELA DE PESOS'!$A$2:$B$9,2,FALSE()),0)) -> 0 | AE11: =IF(OR(A11="",NOT(ISNUMBER(C11))),"",C11+H11+Z11) | AF11: =IF(OR(A11="",AE11=""),0,IFERROR(N11*AE11*VLOOKUP(O11,'TABELA DE PESOS'!$A$2:$B$9,2,FALSE()),0)) -> 0 | AG11: =IF(OR(A11="",P11="",NOT(ISNUMBER(C11))),0,P11*(INT(C11/R11)+1)) -> 0 | AH11: =IF(OR(A11="",P11=""),0,2*((D11-2*F11)+(E11-2*F11))/100+2*10*Q11/1000) -> 1.12 | AI11: =IF(OR(A11="",P11=""),0,IFERROR(AG11*AH11*VLOOKUP(Q11,'TABELA DE PESOS'!$A$2:$B$9,2,FALSE()),0)) -> 0 | AJ11: =IF(OR(A11="",S11="",NOT(ISNUMBER(C11))),0,S11*(INT(C11/U11)+1)) -> 0 | AK11: =IF(OR(A11="",S11=""),0,2*((D11-2*F11)+(E11-2*F11))/100+2*10*T11/1000) -> 0 | AL11: =IF(OR(A11="",S11=""),0,IFERROR(AJ11*AK11*VLOOKUP(T11,'TABELA DE PESOS'!$A$2:$B$9,2,FALSE()),0)) -> 0 | AM11: =IF(OR(A11="",V11="",NOT(ISNUMBER(C11))),0,V11*(INT(C11/X11)+1)) -> 0 | AN11: =IF(OR(A11="",V11=""),0,2*((D11-2*F11)+(E11-2*F11))/100+2*10*W11/1000) -> 0 | AO11: =IF(OR(A11="",V11=""),0,IFERROR(AM11*AN11*VLOOKUP(W11,'TABELA DE PESOS'!$A$2:$B$9,2,FALSE()),0)) -> 0 | AP11: =IF(A11="",0,AB11+AD11+AF11+AI11+AL11+AO11) -> 0 | AQ11: =IF(OR(A11="",NOT(ISNUMBER(C11))),0,(D11/100)*(E11/100)*C11) -> 0 | AR11: =IF(OR(A11="",NOT(ISNUMBER(C11))),0,2*(D11/100+E11/100)*C11) -> 0 | AS11: Fundações a Piso 0. Cinta retangular simples.
A12: P4-P1 | B12: Piso 1 | C12: =IF(B12<>"",IFERROR(VLOOKUP(B12,PISOS!A:D,4,0),"PENDENTE"),"") -> 3.93 | D12: 20 | E12: 40 | F12: 3 | G12: 50 | H12: =IF(OR(A12="",K12=""),0,G12*K12/1000) -> 0.8 | I12: =IF(OR(A12="",K12="",NOT(ISNUMBER(C12))),0,IF((C12+H12)>12,G12*K12/1000,0)) -> 0 | J12: 6 | K12: 16 | L12: 6 | M12: 12 | P12: 1 | Q12: 8 | R12: 0.2 | Y12: =IF(OR(A12="",M12="",NOT(ISNUMBER(C12))),0,IF((C12+H12)>12,G12*M12/1000,0)) -> 0 | Z12: =IF(OR(A12="",O12="",NOT(ISNUMBER(C12))),0,IF((C12+H12)>12,G12*O12/1000,0)) -> 0 | AA12: =IF(OR(A12="",NOT(ISNUMBER(C12))),"",C12+H12+I12) -> 4.73 | AB12: =IF(OR(A12="",AA12=""),0,IFERROR(J12*AA12*VLOOKUP(K12,'TABELA DE PESOS'!$A$2:$B$9,2,FALSE()),0)) -> 44.78364 | AC12: =IF(OR(A12="",NOT(ISNUMBER(C12))),"",C12+H12+Y12) -> 4.73 | AD12: =IF(OR(A12="",AC12=""),0,IFERROR(L12*AC12*VLOOKUP(M12,'TABELA DE PESOS'!$A$2:$B$9,2,FALSE()),0)) -> 25.20144 | AE12: =IF(OR(A12="",NOT(ISNUMBER(C12))),"",C12+H12+Z12) -> 4.73 | AF12: =IF(OR(A12="",AE12=""),0,IFERROR(N12*AE12*VLOOKUP(O12,'TABELA DE PESOS'!$A$2:$B$9,2,FALSE()),0)) -> 0 | AG12: =IF(OR(A12="",P12="",NOT(ISNUMBER(C12))),0,P12*(INT(C12/R12)+1)) -> 20 | AH12: =IF(OR(A12="",P12=""),0,2*((D12-2*F12)+(E12-2*F12))/100+2*10*Q12/1000) -> 1.12 | AI12: =IF(OR(A12="",P12=""),0,IFERROR(AG12*AH12*VLOOKUP(Q12,'TABELA DE PESOS'!$A$2:$B$9,2,FALSE()),0)) -> 8.848 | AJ12: =IF(OR(A12="",S12="",NOT(ISNUMBER(C12))),0,S12*(INT(C12/U12)+1)) -> 0 | AK12: =IF(OR(A12="",S12=""),0,2*((D12-2*F12)+(E12-2*F12))/100+2*10*T12/1000) -> 0 | AL12: =IF(OR(A12="",S12=""),0,IFERROR(AJ12*AK12*VLOOKUP(T12,'TABELA DE PESOS'!$A$2:$B$9,2,FALSE()),0)) -> 0 | AM12: =IF(OR(A12="",V12="",NOT(ISNUMBER(C12))),0,V12*(INT(C12/X12)+1)) -> 0 | AN12: =IF(OR(A12="",V12=""),0,2*((D12-2*F12)+(E12-2*F12))/100+2*10*W12/1000) -> 0 | AO12: =IF(OR(A12="",V12=""),0,IFERROR(AM12*AN12*VLOOKUP(W12,'TABELA DE PESOS'!$A$2:$B$9,2,FALSE()),0)) -> 0 | AP12: =IF(A12="",0,AB12+AD12+AF12+AI12+AL12+AO12) -> 78.83308 | AQ12: =IF(OR(A12="",NOT(ISNUMBER(C12))),0,(D12/100)*(E12/100)*C12) -> 0.3144 | AR12: =IF(OR(A12="",NOT(ISNUMBER(C12))),0,2*(D12/100+E12/100)*C12) -> 4.716 | AS12: Piso 0 a Piso 1. Cinta retangular simples.
A13: P4-COB | B13: Cobertura | C13: =IF(B13<>"",IFERROR(VLOOKUP(B13,PISOS!A:D,4,0),"PENDENTE"),"") -> PENDENTE | D13: 20 | E13: 40 | F13: 3 | G13: 50 | H13: =IF(OR(A13="",K13=""),0,G13*K13/1000) -> 0.8 | I13: =IF(OR(A13="",K13="",NOT(ISNUMBER(C13))),0,IF((C13+H13)>12,G13*K13/1000,0)) -> 0 | J13: 6 | K13: 16 | L13: 6 | M13: 12 | P13: 1 | Q13: 8 | R13: 0.2 | Y13: =IF(OR(A13="",M13="",NOT(ISNUMBER(C13))),0,IF((C13+H13)>12,G13*M13/1000,0)) -> 0 | Z13: =IF(OR(A13="",O13="",NOT(ISNUMBER(C13))),0,IF((C13+H13)>12,G13*O13/1000,0)) -> 0 | AA13: =IF(OR(A13="",NOT(ISNUMBER(C13))),"",C13+H13+I13) | AB13: =IF(OR(A13="",AA13=""),0,IFERROR(J13*AA13*VLOOKUP(K13,'TABELA DE PESOS'!$A$2:$B$9,2,FALSE()),0)) -> 0 | AC13: =IF(OR(A13="",NOT(ISNUMBER(C13))),"",C13+H13+Y13) | AD13: =IF(OR(A13="",AC13=""),0,IFERROR(L13*AC13*VLOOKUP(M13,'TABELA DE PESOS'!$A$2:$B$9,2,FALSE()),0)) -> 0 | AE13: =IF(OR(A13="",NOT(ISNUMBER(C13))),"",C13+H13+Z13) | AF13: =IF(OR(A13="",AE13=""),0,IFERROR(N13*AE13*VLOOKUP(O13,'TABELA DE PESOS'!$A$2:$B$9,2,FALSE()),0)) -> 0 | AG13: =IF(OR(A13="",P13="",NOT(ISNUMBER(C13))),0,P13*(INT(C13/R13)+1)) -> 0 | AH13: =IF(OR(A13="",P13=""),0,2*((D13-2*F13)+(E13-2*F13))/100+2*10*Q13/1000) -> 1.12 | AI13: =IF(OR(A13="",P13=""),0,IFERROR(AG13*AH13*VLOOKUP(Q13,'TABELA DE PESOS'!$A$2:$B$9,2,FALSE()),0)) -> 0 | AJ13: =IF(OR(A13="",S13="",NOT(ISNUMBER(C13))),0,S13*(INT(C13/U13)+1)) -> 0 | AK13: =IF(OR(A13="",S13=""),0,2*((D13-2*F13)+(E13-2*F13))/100+2*10*T13/1000) -> 0 | AL13: =IF(OR(A13="",S13=""),0,IFERROR(AJ13*AK13*VLOOKUP(T13,'TABELA DE PESOS'!$A$2:$B$9,2,FALSE()),0)) -> 0 | AM13: =IF(OR(A13="",V13="",NOT(ISNUMBER(C13))),0,V13*(INT(C13/X13)+1)) -> 0 | AN13: =IF(OR(A13="",V13=""),0,2*((D13-2*F13)+(E13-2*F13))/100+2*10*W13/1000) -> 0 | AO13: =IF(OR(A13="",V13=""),0,IFERROR(AM13*AN13*VLOOKUP(W13,'TABELA DE PESOS'!$A$2:$B$9,2,FALSE()),0)) -> 0 | AP13: =IF(A13="",0,AB13+AD13+AF13+AI13+AL13+AO13) -> 0 | AQ13: =IF(OR(A13="",NOT(ISNUMBER(C13))),0,(D13/100)*(E13/100)*C13) -> 0 | AR13: =IF(OR(A13="",NOT(ISNUMBER(C13))),0,2*(D13/100+E13/100)*C13) -> 0 | AS13: Piso 1 a Cobertura. Cinta retangular simples.
A14: P5-P1 | B14: Piso 1 | C14: =IF(B14<>"",IFERROR(VLOOKUP(B14,PISOS!A:D,4,0),"PENDENTE"),"") -> 3.93 | D14: 20 | E14: 40 | F14: 3 | G14: 50 | H14: =IF(OR(A14="",K14=""),0,G14*K14/1000) -> 0.8 | I14: =IF(OR(A14="",K14="",NOT(ISNUMBER(C14))),0,IF((C14+H14)>12,G14*K14/1000,0)) -> 0 | J14: 6 | K14: 16 | L14: 6 | M14: 12 | P14: 1 | Q14: 8 | R14: 0.2 | Y14: =IF(OR(A14="",M14="",NOT(ISNUMBER(C14))),0,IF((C14+H14)>12,G14*M14/1000,0)) -> 0 | Z14: =IF(OR(A14="",O14="",NOT(ISNUMBER(C14))),0,IF((C14+H14)>12,G14*O14/1000,0)) -> 0 | AA14: =IF(OR(A14="",NOT(ISNUMBER(C14))),"",C14+H14+I14) -> 4.73 | AB14: =IF(OR(A14="",AA14=""),0,IFERROR(J14*AA14*VLOOKUP(K14,'TABELA DE PESOS'!$A$2:$B$9,2,FALSE()),0)) -> 44.78364 | AC14: =IF(OR(A14="",NOT(ISNUMBER(C14))),"",C14+H14+Y14) -> 4.73 | AD14: =IF(OR(A14="",AC14=""),0,IFERROR(L14*AC14*VLOOKUP(M14,'TABELA DE PESOS'!$A$2:$B$9,2,FALSE()),0)) -> 25.20144 | AE14: =IF(OR(A14="",NOT(ISNUMBER(C14))),"",C14+H14+Z14) -> 4.73 | AF14: =IF(OR(A14="",AE14=""),0,IFERROR(N14*AE14*VLOOKUP(O14,'TABELA DE PESOS'!$A$2:$B$9,2,FALSE()),0)) -> 0 | AG14: =IF(OR(A14="",P14="",NOT(ISNUMBER(C14))),0,P14*(INT(C14/R14)+1)) -> 20 | AH14: =IF(OR(A14="",P14=""),0,2*((D14-2*F14)+(E14-2*F14))/100+2*10*Q14/1000) -> 1.12 | AI14: =IF(OR(A14="",P14=""),0,IFERROR(AG14*AH14*VLOOKUP(Q14,'TABELA DE PESOS'!$A$2:$B$9,2,FALSE()),0)) -> 8.848 | AJ14: =IF(OR(A14="",S14="",NOT(ISNUMBER(C14))),0,S14*(INT(C14/U14)+1)) -> 0 | AK14: =IF(OR(A14="",S14=""),0,2*((D14-2*F14)+(E14-2*F14))/100+2*10*T14/1000) -> 0 | AL14: =IF(OR(A14="",S14=""),0,IFERROR(AJ14*AK14*VLOOKUP(T14,'TABELA DE PESOS'!$A$2:$B$9,2,FALSE()),0)) -> 0 | AM14: =IF(OR(A14="",V14="",NOT(ISNUMBER(C14))),0,V14*(INT(C14/X14)+1)) -> 0 | AN14: =IF(OR(A14="",V14=""),0,2*((D14-2*F14)+(E14-2*F14))/100+2*10*W14/1000) -> 0 | AO14: =IF(OR(A14="",V14=""),0,IFERROR(AM14*AN14*VLOOKUP(W14,'TABELA DE PESOS'!$A$2:$B$9,2,FALSE()),0)) -> 0 | AP14: =IF(A14="",0,AB14+AD14+AF14+AI14+AL14+AO14) -> 78.83308 | AQ14: =IF(OR(A14="",NOT(ISNUMBER(C14))),0,(D14/100)*(E14/100)*C14) -> 0.3144 | AR14: =IF(OR(A14="",NOT(ISNUMBER(C14))),0,2*(D14/100+E14/100)*C14) -> 4.716 | AS14: Piso 0 a Piso 1. Cinta retangular simples.
A15: P6-P0 | B15: Piso 0 | C15: =IF(B15<>"",IFERROR(VLOOKUP(B15,PISOS!A:D,4,0),"PENDENTE"),"") -> PENDENTE | D15: 30 | E15: 30 | F15: 3 | G15: 50 | H15: =IF(OR(A15="",K15=""),0,G15*K15/1000) -> 1 | I15: =IF(OR(A15="",K15="",NOT(ISNUMBER(C15))),0,IF((C15+H15)>12,G15*K15/1000,0)) -> 0 | J15: 8 | K15: 20 | L15: 4 | M15: 16 | P15: 1 | Q15: 8 | R15: 0.2 | Y15: =IF(OR(A15="",M15="",NOT(ISNUMBER(C15))),0,IF((C15+H15)>12,G15*M15/1000,0)) -> 0 | Z15: =IF(OR(A15="",O15="",NOT(ISNUMBER(C15))),0,IF((C15+H15)>12,G15*O15/1000,0)) -> 0 | AA15: =IF(OR(A15="",NOT(ISNUMBER(C15))),"",C15+H15+I15) | AB15: =IF(OR(A15="",AA15=""),0,IFERROR(J15*AA15*VLOOKUP(K15,'TABELA DE PESOS'!$A$2:$B$9,2,FALSE()),0)) -> 0 | AC15: =IF(OR(A15="",NOT(ISNUMBER(C15))),"",C15+H15+Y15) | AD15: =IF(OR(A15="",AC15=""),0,IFERROR(L15*AC15*VLOOKUP(M15,'TABELA DE PESOS'!$A$2:$B$9,2,FALSE()),0)) -> 0 | AE15: =IF(OR(A15="",NOT(ISNUMBER(C15))),"",C15+H15+Z15) | AF15: =IF(OR(A15="",AE15=""),0,IFERROR(N15*AE15*VLOOKUP(O15,'TABELA DE PESOS'!$A$2:$B$9,2,FALSE()),0)) -> 0 | AG15: =IF(OR(A15="",P15="",NOT(ISNUMBER(C15))),0,P15*(INT(C15/R15)+1)) -> 0 | AH15: =IF(OR(A15="",P15=""),0,2*((D15-2*F15)+(E15-2*F15))/100+2*10*Q15/1000) -> 1.12 | AI15: =IF(OR(A15="",P15=""),0,IFERROR(AG15*AH15*VLOOKUP(Q15,'TABELA DE PESOS'!$A$2:$B$9,2,FALSE()),0)) -> 0 | AJ15: =IF(OR(A15="",S15="",NOT(ISNUMBER(C15))),0,S15*(INT(C15/U15)+1)) -> 0 | AK15: =IF(OR(A15="",S15=""),0,2*((D15-2*F15)+(E15-2*F15))/100+2*10*T15/1000) -> 0 | AL15: =IF(OR(A15="",S15=""),0,IFERROR(AJ15*AK15*VLOOKUP(T15,'TABELA DE PESOS'!$A$2:$B$9,2,FALSE()),0)) -> 0 | AM15: =IF(OR(A15="",V15="",NOT(ISNUMBER(C15))),0,V15*(INT(C15/X15)+1)) -> 0 | AN15: =IF(OR(A15="",V15=""),0,2*((D15-2*F15)+(E15-2*F15))/100+2*10*W15/1000) -> 0 | AO15: =IF(OR(A15="",V15=""),0,IFERROR(AM15*AN15*VLOOKUP(W15,'TABELA DE PESOS'!$A$2:$B$9,2,FALSE()),0)) -> 0 | AP15: =IF(A15="",0,AB15+AD15+AF15+AI15+AL15+AO15) -> 0 | AQ15: =IF(OR(A15="",NOT(ISNUMBER(C15))),0,(D15/100)*(E15/100)*C15) -> 0 | AR15: =IF(OR(A15="",NOT(ISNUMBER(C15))),0,2*(D15/100+E15/100)*C15) -> 0 | AS15: Fundações a Piso 0. Cinta retangular. Encontro com parede no troço inferior.
A16: P6-P1 | B16: Piso 1 | C16: =IF(B16<>"",IFERROR(VLOOKUP(B16,PISOS!A:D,4,0),"PENDENTE"),"") -> 3.93 | D16: 30 | E16: 30 | F16: 3 | G16: 50 | H16: =IF(OR(A16="",K16=""),0,G16*K16/1000) -> 1 | I16: =IF(OR(A16="",K16="",NOT(ISNUMBER(C16))),0,IF((C16+H16)>12,G16*K16/1000,0)) -> 0 | J16: 8 | K16: 20 | L16: 4 | M16: 16 | P16: 1 | Q16: 8 | R16: 0.2 | Y16: =IF(OR(A16="",M16="",NOT(ISNUMBER(C16))),0,IF((C16+H16)>12,G16*M16/1000,0)) -> 0 | Z16: =IF(OR(A16="",O16="",NOT(ISNUMBER(C16))),0,IF((C16+H16)>12,G16*O16/1000,0)) -> 0 | AA16: =IF(OR(A16="",NOT(ISNUMBER(C16))),"",C16+H16+I16) -> 4.93 | AB16: =IF(OR(A16="",AA16=""),0,IFERROR(J16*AA16*VLOOKUP(K16,'TABELA DE PESOS'!$A$2:$B$9,2,FALSE()),0)) -> 97.25904 | AC16: =IF(OR(A16="",NOT(ISNUMBER(C16))),"",C16+H16+Y16) -> 4.93 | AD16: =IF(OR(A16="",AC16=""),0,IFERROR(L16*AC16*VLOOKUP(M16,'TABELA DE PESOS'!$A$2:$B$9,2,FALSE()),0)) -> 31.11816 | AE16: =IF(OR(A16="",NOT(ISNUMBER(C16))),"",C16+H16+Z16) -> 4.93 | AF16: =IF(OR(A16="",AE16=""),0,IFERROR(N16*AE16*VLOOKUP(O16,'TABELA DE PESOS'!$A$2:$B$9,2,FALSE()),0)) -> 0 | AG16: =IF(OR(A16="",P16="",NOT(ISNUMBER(C16))),0,P16*(INT(C16/R16)+1)) -> 20 | AH16: =IF(OR(A16="",P16=""),0,2*((D16-2*F16)+(E16-2*F16))/100+2*10*Q16/1000) -> 1.12 | AI16: =IF(OR(A16="",P16=""),0,IFERROR(AG16*AH16*VLOOKUP(Q16,'TABELA DE PESOS'!$A$2:$B$9,2,FALSE()),0)) -> 8.848 | AJ16: =IF(OR(A16="",S16="",NOT(ISNUMBER(C16))),0,S16*(INT(C16/U16)+1)) -> 0 | AK16: =IF(OR(A16="",S16=""),0,2*((D16-2*F16)+(E16-2*F16))/100+2*10*T16/1000) -> 0 | AL16: =IF(OR(A16="",S16=""),0,IFERROR(AJ16*AK16*VLOOKUP(T16,'TABELA DE PESOS'!$A$2:$B$9,2,FALSE()),0)) -> 0 | AM16: =IF(OR(A16="",V16="",NOT(ISNUMBER(C16))),0,V16*(INT(C16/X16)+1)) -> 0 | AN16: =IF(OR(A16="",V16=""),0,2*((D16-2*F16)+(E16-2*F16))/100+2*10*W16/1000) -> 0 | AO16: =IF(OR(A16="",V16=""),0,IFERROR(AM16*AN16*VLOOKUP(W16,'TABELA DE PESOS'!$A$2:$B$9,2,FALSE()),0)) -> 0 | AP16: =IF(A16="",0,AB16+AD16+AF16+AI16+AL16+AO16) -> 137.2252 | AQ16: =IF(OR(A16="",NOT(ISNUMBER(C16))),0,(D16/100)*(E16/100)*C16) -> 0.3537 | AR16: =IF(OR(A16="",NOT(ISNUMBER(C16))),0,2*(D16/100+E16/100)*C16) -> 4.716 | AS16: Piso 0 a Piso 1. Cinta retangular. Encontro com parede no troço inferior.
A17: P7-P0 | B17: Piso 0 | C17: =IF(B17<>"",IFERROR(VLOOKUP(B17,PISOS!A:D,4,0),"PENDENTE"),"") -> PENDENTE | D17: 50 | E17: 30 | F17: 3 | G17: 50 | H17: =IF(OR(A17="",K17=""),0,G17*K17/1000) -> 0.8 | I17: =IF(OR(A17="",K17="",NOT(ISNUMBER(C17))),0,IF((C17+H17)>12,G17*K17/1000,0)) -> 0 | J17: 10 | K17: 16 | P17: 1 | Q17: 8 | R17: 0.2 | Y17: =IF(OR(A17="",M17="",NOT(ISNUMBER(C17))),0,IF((C17+H17)>12,G17*M17/1000,0)) -> 0 | Z17: =IF(OR(A17="",O17="",NOT(ISNUMBER(C17))),0,IF((C17+H17)>12,G17*O17/1000,0)) -> 0 | AA17: =IF(OR(A17="",NOT(ISNUMBER(C17))),"",C17+H17+I17) | AB17: =IF(OR(A17="",AA17=""),0,IFERROR(J17*AA17*VLOOKUP(K17,'TABELA DE PESOS'!$A$2:$B$9,2,FALSE()),0)) -> 0 | AC17: =IF(OR(A17="",NOT(ISNUMBER(C17))),"",C17+H17+Y17) | AD17: =IF(OR(A17="",AC17=""),0,IFERROR(L17*AC17*VLOOKUP(M17,'TABELA DE PESOS'!$A$2:$B$9,2,FALSE()),0)) -> 0 | AE17: =IF(OR(A17="",NOT(ISNUMBER(C17))),"",C17+H17+Z17) | AF17: =IF(OR(A17="",AE17=""),0,IFERROR(N17*AE17*VLOOKUP(O17,'TABELA DE PESOS'!$A$2:$B$9,2,FALSE()),0)) -> 0 | AG17: =IF(OR(A17="",P17="",NOT(ISNUMBER(C17))),0,P17*(INT(C17/R17)+1)) -> 0 | AH17: =IF(OR(A17="",P17=""),0,2*((D17-2*F17)+(E17-2*F17))/100+2*10*Q17/1000) -> 1.52 | AI17: =IF(OR(A17="",P17=""),0,IFERROR(AG17*AH17*VLOOKUP(Q17,'TABELA DE PESOS'!$A$2:$B$9,2,FALSE()),0)) -> 0 | AJ17: =IF(OR(A17="",S17="",NOT(ISNUMBER(C17))),0,S17*(INT(C17/U17)+1)) -> 0 | AK17: =IF(OR(A17="",S17=""),0,2*((D17-2*F17)+(E17-2*F17))/100+2*10*T17/1000) -> 0 | AL17: =IF(OR(A17="",S17=""),0,IFERROR(AJ17*AK17*VLOOKUP(T17,'TABELA DE PESOS'!$A$2:$B$9,2,FALSE()),0)) -> 0 | AM17: =IF(OR(A17="",V17="",NOT(ISNUMBER(C17))),0,V17*(INT(C17/X17)+1)) -> 0 | AN17: =IF(OR(A17="",V17=""),0,2*((D17-2*F17)+(E17-2*F17))/100+2*10*W17/1000) -> 0 | AO17: =IF(OR(A17="",V17=""),0,IFERROR(AM17*AN17*VLOOKUP(W17,'TABELA DE PESOS'!$A$2:$B$9,2,FALSE()),0)) -> 0 | AP17: =IF(A17="",0,AB17+AD17+AF17+AI17+AL17+AO17) -> 0 | AQ17: =IF(OR(A17="",NOT(ISNUMBER(C17))),0,(D17/100)*(E17/100)*C17) -> 0 | AR17: =IF(OR(A17="",NOT(ISNUMBER(C17))),0,2*(D17/100+E17/100)*C17) -> 0 | AS17: Fundações a Piso 0. Cinta retangular. Encontro com parede. Seção base diferente (50×30).
A18: P7-P1 | B18: Piso 1 | C18: =IF(B18<>"",IFERROR(VLOOKUP(B18,PISOS!A:D,4,0),"PENDENTE"),"") -> 3.93 | D18: 30 | E18: 30 | F18: 3 | G18: 50 | H18: =IF(OR(A18="",K18=""),0,G18*K18/1000) -> 0.8 | I18: =IF(OR(A18="",K18="",NOT(ISNUMBER(C18))),0,IF((C18+H18)>12,G18*K18/1000,0)) -> 0 | J18: 7 | K18: 16 | P18: 1 | Q18: 8 | R18: 0.2 | Y18: =IF(OR(A18="",M18="",NOT(ISNUMBER(C18))),0,IF((C18+H18)>12,G18*M18/1000,0)) -> 0 | Z18: =IF(OR(A18="",O18="",NOT(ISNUMBER(C18))),0,IF((C18+H18)>12,G18*O18/1000,0)) -> 0 | AA18: =IF(OR(A18="",NOT(ISNUMBER(C18))),"",C18+H18+I18) -> 4.73 | AB18: =IF(OR(A18="",AA18=""),0,IFERROR(J18*AA18*VLOOKUP(K18,'TABELA DE PESOS'!$A$2:$B$9,2,FALSE()),0)) -> 52.24758 | AC18: =IF(OR(A18="",NOT(ISNUMBER(C18))),"",C18+H18+Y18) -> 4.73 | AD18: =IF(OR(A18="",AC18=""),0,IFERROR(L18*AC18*VLOOKUP(M18,'TABELA DE PESOS'!$A$2:$B$9,2,FALSE()),0)) -> 0 | AE18: =IF(OR(A18="",NOT(ISNUMBER(C18))),"",C18+H18+Z18) -> 4.73 | AF18: =IF(OR(A18="",AE18=""),0,IFERROR(N18*AE18*VLOOKUP(O18,'TABELA DE PESOS'!$A$2:$B$9,2,FALSE()),0)) -> 0 | AG18: =IF(OR(A18="",P18="",NOT(ISNUMBER(C18))),0,P18*(INT(C18/R18)+1)) -> 20 | AH18: =IF(OR(A18="",P18=""),0,PI()*(D18-2*F18)/100+2*10*Q18/1000) -> 0.91398224 | AI18: =IF(OR(A18="",P18=""),0,IFERROR(AG18*AH18*VLOOKUP(Q18,'TABELA DE PESOS'!$A$2:$B$9,2,FALSE()),0)) -> 7.2204597 | AJ18: =IF(OR(A18="",S18="",NOT(ISNUMBER(C18))),0,S18*(INT(C18/U18)+1)) -> 0 | AK18: =IF(OR(A18="",S18=""),0,PI()*(D18-2*F18)/100+2*10*T18/1000) -> 0 | AL18: =IF(OR(A18="",S18=""),0,IFERROR(AJ18*AK18*VLOOKUP(T18,'TABELA DE PESOS'!$A$2:$B$9,2,FALSE()),0)) -> 0 | AM18: =IF(OR(A18="",V18="",NOT(ISNUMBER(C18))),0,V18*(INT(C18/X18)+1)) -> 0 | AN18: =IF(OR(A18="",V18=""),0,PI()*(D18-2*F18)/100+2*10*W18/1000) -> 0 | AO18: =IF(OR(A18="",V18=""),0,IFERROR(AM18*AN18*VLOOKUP(W18,'TABELA DE PESOS'!$A$2:$B$9,2,FALSE()),0)) -> 0 | AP18: =IF(A18="",0,AB18+AD18+AF18+AI18+AL18+AO18) -> 59.46804 | AQ18: =IF(OR(A18="",NOT(ISNUMBER(C18))),0,PI()*(D18/200)^2*C18) -> 0.27779533 | AR18: =IF(OR(A18="",NOT(ISNUMBER(C18))),0,PI()*(D18/100)*C18) -> 3.7039377 | AS18: Piso 0 a Piso 1. Cinta circular Ø30. Mapa não identifica espiral contínua.
A19: P7-COB | B19: Cobertura | C19: =IF(B19<>"",IFERROR(VLOOKUP(B19,PISOS!A:D,4,0),"PENDENTE"),"") -> PENDENTE | D19: 30 | E19: 30 | F19: 3 | G19: 50 | H19: =IF(OR(A19="",K19=""),0,G19*K19/1000) -> 0.8 | I19: =IF(OR(A19="",K19="",NOT(ISNUMBER(C19))),0,IF((C19+H19)>12,G19*K19/1000,0)) -> 0 | J19: 7 | K19: 16 | P19: 1 | Q19: 8 | R19: 0.2 | Y19: =IF(OR(A19="",M19="",NOT(ISNUMBER(C19))),0,IF((C19+H19)>12,G19*M19/1000,0)) -> 0 | Z19: =IF(OR(A19="",O19="",NOT(ISNUMBER(C19))),0,IF((C19+H19)>12,G19*O19/1000,0)) -> 0 | AA19: =IF(OR(A19="",NOT(ISNUMBER(C19))),"",C19+H19+I19) | AB19: =IF(OR(A19="",AA19=""),0,IFERROR(J19*AA19*VLOOKUP(K19,'TABELA DE PESOS'!$A$2:$B$9,2,FALSE()),0)) -> 0 | AC19: =IF(OR(A19="",NOT(ISNUMBER(C19))),"",C19+H19+Y19) | AD19: =IF(OR(A19="",AC19=""),0,IFERROR(L19*AC19*VLOOKUP(M19,'TABELA DE PESOS'!$A$2:$B$9,2,FALSE()),0)) -> 0 | AE19: =IF(OR(A19="",NOT(ISNUMBER(C19))),"",C19+H19+Z19) | AF19: =IF(OR(A19="",AE19=""),0,IFERROR(N19*AE19*VLOOKUP(O19,'TABELA DE PESOS'!$A$2:$B$9,2,FALSE()),0)) -> 0 | AG19: =IF(OR(A19="",P19="",NOT(ISNUMBER(C19))),0,P19*(INT(C19/R19)+1)) -> 0 | AH19: =IF(OR(A19="",P19=""),0,PI()*(D19-2*F19)/100+2*10*Q19/1000) -> 0.91398224 | AI19: =IF(OR(A19="",P19=""),0,IFERROR(AG19*AH19*VLOOKUP(Q19,'TABELA DE PESOS'!$A$2:$B$9,2,FALSE()),0)) -> 0 | AJ19: =IF(OR(A19="",S19="",NOT(ISNUMBER(C19))),0,S19*(INT(C19/U19)+1)) -> 0 | AK19: =IF(OR(A19="",S19=""),0,PI()*(D19-2*F19)/100+2*10*T19/1000) -> 0 | AL19: =IF(OR(A19="",S19=""),0,IFERROR(AJ19*AK19*VLOOKUP(T19,'TABELA DE PESOS'!$A$2:$B$9,2,FALSE()),0)) -> 0 | AM19: =IF(OR(A19="",V19="",NOT(ISNUMBER(C19))),0,V19*(INT(C19/X19)+1)) -> 0 | AN19: =IF(OR(A19="",V19=""),0,PI()*(D19-2*F19)/100+2*10*W19/1000) -> 0 | AO19: =IF(OR(A19="",V19=""),0,IFERROR(AM19*AN19*VLOOKUP(W19,'TABELA DE PESOS'!$A$2:$B$9,2,FALSE()),0)) -> 0 | AP19: =IF(A19="",0,AB19+AD19+AF19+AI19+AL19+AO19) -> 0 | AQ19: =IF(OR(A19="",NOT(ISNUMBER(C19))),0,PI()*(D19/200)^2*C19) -> 0 | AR19: =IF(OR(A19="",NOT(ISNUMBER(C19))),0,PI()*(D19/100)*C19) -> 0 | AS19: Piso 1 a Cobertura. Cinta circular Ø30. Mapa não identifica espiral contínua.
A20: P8-P0 | B20: Piso 0 | C20: =IF(B20<>"",IFERROR(VLOOKUP(B20,PISOS!A:D,4,0),"PENDENTE"),"") -> PENDENTE | D20: 30 | E20: 60 | F20: 3 | G20: 50 | H20: =IF(OR(A20="",K20=""),0,G20*K20/1000) -> 0.8 | I20: =IF(OR(A20="",K20="",NOT(ISNUMBER(C20))),0,IF((C20+H20)>12,G20*K20/1000,0)) -> 0 | J20: 6 | K20: 16 | L20: 10 | M20: 12 | P20: 1 | Q20: 8 | R20: 0.2 | S20: 1 | T20: 8 | U20: 0.2 | Y20: =IF(OR(A20="",M20="",NOT(ISNUMBER(C20))),0,IF((C20+H20)>12,G20*M20/1000,0)) -> 0 | Z20: =IF(OR(A20="",O20="",NOT(ISNUMBER(C20))),0,IF((C20+H20)>12,G20*O20/1000,0)) -> 0 | AA20: =IF(OR(A20="",NOT(ISNUMBER(C20))),"",C20+H20+I20) | AB20: =IF(OR(A20="",AA20=""),0,IFERROR(J20*AA20*VLOOKUP(K20,'TABELA DE PESOS'!$A$2:$B$9,2,FALSE()),0)) -> 0 | AC20: =IF(OR(A20="",NOT(ISNUMBER(C20))),"",C20+H20+Y20) | AD20: =IF(OR(A20="",AC20=""),0,IFERROR(L20*AC20*VLOOKUP(M20,'TABELA DE PESOS'!$A$2:$B$9,2,FALSE()),0)) -> 0 | AE20: =IF(OR(A20="",NOT(ISNUMBER(C20))),"",C20+H20+Z20) | AF20: =IF(OR(A20="",AE20=""),0,IFERROR(N20*AE20*VLOOKUP(O20,'TABELA DE PESOS'!$A$2:$B$9,2,FALSE()),0)) -> 0 | AG20: =IF(OR(A20="",P20="",NOT(ISNUMBER(C20))),0,P20*(INT(C20/R20)+1)) -> 0 | AH20: =IF(OR(A20="",P20=""),0,2*((D20-2*F20)+(E20-2*F20))/100+2*10*Q20/1000) -> 1.72 | AI20: =IF(OR(A20="",P20=""),0,IFERROR(AG20*AH20*VLOOKUP(Q20,'TABELA DE PESOS'!$A$2:$B$9,2,FALSE()),0)) -> 0 | AJ20: =IF(OR(A20="",S20="",NOT(ISNUMBER(C20))),0,S20*(INT(C20/U20)+1)) -> 0 | AK20: =IF(OR(A20="",S20=""),0,2*((D20-2*F20)+(E20-2*F20))/100+2*10*T20/1000) -> 1.72 | AL20: =IF(OR(A20="",S20=""),0,IFERROR(AJ20*AK20*VLOOKUP(T20,'TABELA DE PESOS'!$A$2:$B$9,2,FALSE()),0)) -> 0 | AM20: =IF(OR(A20="",V20="",NOT(ISNUMBER(C20))),0,V20*(INT(C20/X20)+1)) -> 0 | AN20: =IF(OR(A20="",V20=""),0,2*((D20-2*F20)+(E20-2*F20))/100+2*10*W20/1000) -> 0 | AO20: =IF(OR(A20="",V20=""),0,IFERROR(AM20*AN20*VLOOKUP(W20,'TABELA DE PESOS'!$A$2:$B$9,2,FALSE()),0)) -> 0 | AP20: =IF(A20="",0,AB20+AD20+AF20+AI20+AL20+AO20) -> 0 | AQ20: =IF(OR(A20="",NOT(ISNUMBER(C20))),0,(D20/100)*(E20/100)*C20) -> 0 | AR20: =IF(OR(A20="",NOT(ISNUMBER(C20))),0,2*(D20/100+E20/100)*C20) -> 0 | AS20: Fundações a Piso 0. Cinta exterior e cinta interior fechada. Contagem cintas exige zonas a/2.
A21: P8-P1 | B21: Piso 1 | C21: 3.9 | D21: 30 | E21: 60 | F21: 3 | G21: 50 | H21: =IF(OR(A21="",K21=""),0,G21*K21/1000) -> 0.8 | I21: =IF(OR(A21="",K21="",NOT(ISNUMBER(C21))),0,IF((C21+H21)>12,G21*K21/1000,0)) -> 0 | J21: 6 | K21: 16 | L21: 10 | M21: 12 | P21: 1 | Q21: 8 | R21: 0.2 | S21: 1 | T21: 8 | U21: 0.2 | Y21: =IF(OR(A21="",M21="",NOT(ISNUMBER(C21))),0,IF((C21+H21)>12,G21*M21/1000,0)) -> 0 | Z21: =IF(OR(A21="",O21="",NOT(ISNUMBER(C21))),0,IF((C21+H21)>12,G21*O21/1000,0)) -> 0 | AA21: =IF(OR(A21="",NOT(ISNUMBER(C21))),"",C21+H21+I21) -> 4.7 | AB21: =IF(OR(A21="",AA21=""),0,IFERROR(J21*AA21*VLOOKUP(K21,'TABELA DE PESOS'!$A$2:$B$9,2,FALSE()),0)) -> 44.4996 | AC21: =IF(OR(A21="",NOT(ISNUMBER(C21))),"",C21+H21+Y21) -> 4.7 | AD21: =IF(OR(A21="",AC21=""),0,IFERROR(L21*AC21*VLOOKUP(M21,'TABELA DE PESOS'!$A$2:$B$9,2,FALSE()),0)) -> 41.736 | AE21: =IF(OR(A21="",NOT(ISNUMBER(C21))),"",C21+H21+Z21) -> 4.7 | AF21: =IF(OR(A21="",AE21=""),0,IFERROR(N21*AE21*VLOOKUP(O21,'TABELA DE PESOS'!$A$2:$B$9,2,FALSE()),0)) -> 0 | AG21: =IF(OR(A21="",P21="",NOT(ISNUMBER(C21))),0,P21*(INT(C21/R21)+1)) -> 20 | AH21: =IF(OR(A21="",P21=""),0,2*((D21-2*F21)+(E21-2*F21))/100+2*10*Q21/1000) -> 1.72 | AI21: =IF(OR(A21="",P21=""),0,IFERROR(AG21*AH21*VLOOKUP(Q21,'TABELA DE PESOS'!$A$2:$B$9,2,FALSE()),0)) -> 13.588 | AJ21: =IF(OR(A21="",S21="",NOT(ISNUMBER(C21))),0,S21*(INT(C21/U21)+1)) -> 20 | AK21: =IF(OR(A21="",S21=""),0,2*((D21-2*F21)+(E21-2*F21))/100+2*10*T21/1000) -> 1.72 | AL21: =IF(OR(A21="",S21=""),0,IFERROR(AJ21*AK21*VLOOKUP(T21,'TABELA DE PESOS'!$A$2:$B$9,2,FALSE()),0)) -> 13.588 | AM21: =IF(OR(A21="",V21="",NOT(ISNUMBER(C21))),0,V21*(INT(C21/X21)+1)) -> 0 | AN21: =IF(OR(A21="",V21=""),0,2*((D21-2*F21)+(E21-2*F21))/100+2*10*W21/1000) -> 0 | AO21: =IF(OR(A21="",V21=""),0,IFERROR(AM21*AN21*VLOOKUP(W21,'TABELA DE PESOS'!$A$2:$B$9,2,FALSE()),0)) -> 0 | AP21: =IF(A21="",0,AB21+AD21+AF21+AI21+AL21+AO21) -> 113.4116 | AQ21: =IF(OR(A21="",NOT(ISNUMBER(C21))),0,(D21/100)*(E21/100)*C21) -> 0.702 | AR21: =IF(OR(A21="",NOT(ISNUMBER(C21))),0,2*(D21/100+E21/100)*C21) -> 7.02 | AS21: Piso 0 a Piso 1. H=3,90 m confirmada. Cinta exterior e interior fechada.
